Error Log Started: 2024-12-10 03:45:44.332875
==================================================

Time: 2024-12-10 03:48:39
Error Type: ProcessTeamGamesError
Error Message: Date with year set to 1997, month set to 10, and day set to 31 is invalid
Details: {'team': 'Team.CHARLOTTE_HORNETS', 'date': '1997-10-31', 'year': 1998, 'timestamp': '2024-12-10 03:48:39', 'traceback': 'Traceback (most recent call last):\n  File "/Users/eliyoung/Stat011Project/myenv/lib/python3.13/site-packages/basketball_reference_web_scraper/client.py", line 220, in play_by_play\n    values = http_service.play_by_play(home_team=home_team, day=day, month=month, year=year)\n  File "/Users/eliyoung/Stat011Project/myenv/lib/python3.13/site-packages/basketball_reference_web_scraper/http_service.py", line 100, in play_by_play\n    response.raise_for_status()\n    ~~~~~~~~~~~~~~~~~~~~~~~~~^^\n  File "/Users/eliyoung/Stat011Project/myenv/lib/python3.13/site-packages/requests/models.py", line 1024, in raise_for_status\n    raise HTTPError(http_error_msg, response=self)\nrequests.exceptions.HTTPError: 404 Client Error: Not Found for url: https://www.basketball-reference.com/boxscores/pbp/199710310CHO.html\n\nDuring handling of the above exception, another exception occurred:\n\nTraceback (most recent call last):\n  File "/Users/eliyoung/Stat011Project/FatigueVSFreethrow/dataProcessor.py", line 890, in main\n    yearAnalyzer.process_team_games(allTeams[team], curr_date[0], curr_date[1], curr_date[2], year, attemptCounter)\n    ~~~~~~~~~~~~~~~~~~~~~~~~~~~~~~~^^^^^^^^^^^^^^^^^^^^^^^^^^^^^^^^^^^^^^^^^^^^^^^^^^^^^^^^^^^^^^^^^^^^^^^^^^^^^^^^\n  File "/Users/eliyoung/Stat011Project/FatigueVSFreethrow/dataProcessor.py", line 127, in process_team_games\n    pbp_data = client.play_by_play(\n        home_team=team,\n    ...<2 lines>...\n        day=day\n    )\n  File "/Users/eliyoung/Stat011Project/myenv/lib/python3.13/site-packages/basketball_reference_web_scraper/client.py", line 223, in play_by_play\n    raise InvalidDate(day=day, month=month, year=year)\nbasketball_reference_web_scraper.errors.InvalidDate: Date with year set to 1997, month set to 10, and day set to 31 is invalid\n'}
==================================================

Time: 2024-12-10 03:48:41
Error Type: ProcessTeamGamesError
Error Message: Date with year set to 1997, month set to 11, and day set to 05 is invalid
Details: {'team': 'Team.CHARLOTTE_HORNETS', 'date': '1997-11-05', 'year': 1998, 'timestamp': '2024-12-10 03:48:41', 'traceback': 'Traceback (most recent call last):\n  File "/Users/eliyoung/Stat011Project/myenv/lib/python3.13/site-packages/basketball_reference_web_scraper/client.py", line 220, in play_by_play\n    values = http_service.play_by_play(home_team=home_team, day=day, month=month, year=year)\n  File "/Users/eliyoung/Stat011Project/myenv/lib/python3.13/site-packages/basketball_reference_web_scraper/http_service.py", line 100, in play_by_play\n    response.raise_for_status()\n    ~~~~~~~~~~~~~~~~~~~~~~~~~^^\n  File "/Users/eliyoung/Stat011Project/myenv/lib/python3.13/site-packages/requests/models.py", line 1024, in raise_for_status\n    raise HTTPError(http_error_msg, response=self)\nrequests.exceptions.HTTPError: 404 Client Error: Not Found for url: https://www.basketball-reference.com/boxscores/pbp/199711050CHO.html\n\nDuring handling of the above exception, another exception occurred:\n\nTraceback (most recent call last):\n  File "/Users/eliyoung/Stat011Project/FatigueVSFreethrow/dataProcessor.py", line 890, in main\n    yearAnalyzer.process_team_games(allTeams[team], curr_date[0], curr_date[1], curr_date[2], year, attemptCounter)\n    ~~~~~~~~~~~~~~~~~~~~~~~~~~~~~~~^^^^^^^^^^^^^^^^^^^^^^^^^^^^^^^^^^^^^^^^^^^^^^^^^^^^^^^^^^^^^^^^^^^^^^^^^^^^^^^^\n  File "/Users/eliyoung/Stat011Project/FatigueVSFreethrow/dataProcessor.py", line 127, in process_team_games\n    pbp_data = client.play_by_play(\n        home_team=team,\n    ...<2 lines>...\n        day=day\n    )\n  File "/Users/eliyoung/Stat011Project/myenv/lib/python3.13/site-packages/basketball_reference_web_scraper/client.py", line 223, in play_by_play\n    raise InvalidDate(day=day, month=month, year=year)\nbasketball_reference_web_scraper.errors.InvalidDate: Date with year set to 1997, month set to 11, and day set to 05 is invalid\n'}
==================================================

Time: 2024-12-10 03:48:43
Error Type: ProcessTeamGamesError
Error Message: Date with year set to 1997, month set to 11, and day set to 08 is invalid
Details: {'team': 'Team.CHARLOTTE_HORNETS', 'date': '1997-11-08', 'year': 1998, 'timestamp': '2024-12-10 03:48:43', 'traceback': 'Traceback (most recent call last):\n  File "/Users/eliyoung/Stat011Project/myenv/lib/python3.13/site-packages/basketball_reference_web_scraper/client.py", line 220, in play_by_play\n    values = http_service.play_by_play(home_team=home_team, day=day, month=month, year=year)\n  File "/Users/eliyoung/Stat011Project/myenv/lib/python3.13/site-packages/basketball_reference_web_scraper/http_service.py", line 100, in play_by_play\n    response.raise_for_status()\n    ~~~~~~~~~~~~~~~~~~~~~~~~~^^\n  File "/Users/eliyoung/Stat011Project/myenv/lib/python3.13/site-packages/requests/models.py", line 1024, in raise_for_status\n    raise HTTPError(http_error_msg, response=self)\nrequests.exceptions.HTTPError: 404 Client Error: Not Found for url: https://www.basketball-reference.com/boxscores/pbp/199711080CHO.html\n\nDuring handling of the above exception, another exception occurred:\n\nTraceback (most recent call last):\n  File "/Users/eliyoung/Stat011Project/FatigueVSFreethrow/dataProcessor.py", line 890, in main\n    yearAnalyzer.process_team_games(allTeams[team], curr_date[0], curr_date[1], curr_date[2], year, attemptCounter)\n    ~~~~~~~~~~~~~~~~~~~~~~~~~~~~~~~^^^^^^^^^^^^^^^^^^^^^^^^^^^^^^^^^^^^^^^^^^^^^^^^^^^^^^^^^^^^^^^^^^^^^^^^^^^^^^^^\n  File "/Users/eliyoung/Stat011Project/FatigueVSFreethrow/dataProcessor.py", line 127, in process_team_games\n    pbp_data = client.play_by_play(\n        home_team=team,\n    ...<2 lines>...\n        day=day\n    )\n  File "/Users/eliyoung/Stat011Project/myenv/lib/python3.13/site-packages/basketball_reference_web_scraper/client.py", line 223, in play_by_play\n    raise InvalidDate(day=day, month=month, year=year)\nbasketball_reference_web_scraper.errors.InvalidDate: Date with year set to 1997, month set to 11, and day set to 08 is invalid\n'}
==================================================

Time: 2024-12-10 03:48:45
Error Type: ProcessTeamGamesError
Error Message: Date with year set to 1997, month set to 11, and day set to 15 is invalid
Details: {'team': 'Team.CHARLOTTE_HORNETS', 'date': '1997-11-15', 'year': 1998, 'timestamp': '2024-12-10 03:48:45', 'traceback': 'Traceback (most recent call last):\n  File "/Users/eliyoung/Stat011Project/myenv/lib/python3.13/site-packages/basketball_reference_web_scraper/client.py", line 220, in play_by_play\n    values = http_service.play_by_play(home_team=home_team, day=day, month=month, year=year)\n  File "/Users/eliyoung/Stat011Project/myenv/lib/python3.13/site-packages/basketball_reference_web_scraper/http_service.py", line 100, in play_by_play\n    response.raise_for_status()\n    ~~~~~~~~~~~~~~~~~~~~~~~~~^^\n  File "/Users/eliyoung/Stat011Project/myenv/lib/python3.13/site-packages/requests/models.py", line 1024, in raise_for_status\n    raise HTTPError(http_error_msg, response=self)\nrequests.exceptions.HTTPError: 404 Client Error: Not Found for url: https://www.basketball-reference.com/boxscores/pbp/199711150CHO.html\n\nDuring handling of the above exception, another exception occurred:\n\nTraceback (most recent call last):\n  File "/Users/eliyoung/Stat011Project/FatigueVSFreethrow/dataProcessor.py", line 890, in main\n    yearAnalyzer.process_team_games(allTeams[team], curr_date[0], curr_date[1], curr_date[2], year, attemptCounter)\n    ~~~~~~~~~~~~~~~~~~~~~~~~~~~~~~~^^^^^^^^^^^^^^^^^^^^^^^^^^^^^^^^^^^^^^^^^^^^^^^^^^^^^^^^^^^^^^^^^^^^^^^^^^^^^^^^\n  File "/Users/eliyoung/Stat011Project/FatigueVSFreethrow/dataProcessor.py", line 127, in process_team_games\n    pbp_data = client.play_by_play(\n        home_team=team,\n    ...<2 lines>...\n        day=day\n    )\n  File "/Users/eliyoung/Stat011Project/myenv/lib/python3.13/site-packages/basketball_reference_web_scraper/client.py", line 223, in play_by_play\n    raise InvalidDate(day=day, month=month, year=year)\nbasketball_reference_web_scraper.errors.InvalidDate: Date with year set to 1997, month set to 11, and day set to 15 is invalid\n'}
==================================================

Time: 2024-12-10 03:48:47
Error Type: ProcessTeamGamesError
Error Message: Date with year set to 1997, month set to 11, and day set to 19 is invalid
Details: {'team': 'Team.CHARLOTTE_HORNETS', 'date': '1997-11-19', 'year': 1998, 'timestamp': '2024-12-10 03:48:47', 'traceback': 'Traceback (most recent call last):\n  File "/Users/eliyoung/Stat011Project/myenv/lib/python3.13/site-packages/basketball_reference_web_scraper/client.py", line 220, in play_by_play\n    values = http_service.play_by_play(home_team=home_team, day=day, month=month, year=year)\n  File "/Users/eliyoung/Stat011Project/myenv/lib/python3.13/site-packages/basketball_reference_web_scraper/http_service.py", line 100, in play_by_play\n    response.raise_for_status()\n    ~~~~~~~~~~~~~~~~~~~~~~~~~^^\n  File "/Users/eliyoung/Stat011Project/myenv/lib/python3.13/site-packages/requests/models.py", line 1024, in raise_for_status\n    raise HTTPError(http_error_msg, response=self)\nrequests.exceptions.HTTPError: 404 Client Error: Not Found for url: https://www.basketball-reference.com/boxscores/pbp/199711190CHO.html\n\nDuring handling of the above exception, another exception occurred:\n\nTraceback (most recent call last):\n  File "/Users/eliyoung/Stat011Project/FatigueVSFreethrow/dataProcessor.py", line 890, in main\n    yearAnalyzer.process_team_games(allTeams[team], curr_date[0], curr_date[1], curr_date[2], year, attemptCounter)\n    ~~~~~~~~~~~~~~~~~~~~~~~~~~~~~~~^^^^^^^^^^^^^^^^^^^^^^^^^^^^^^^^^^^^^^^^^^^^^^^^^^^^^^^^^^^^^^^^^^^^^^^^^^^^^^^^\n  File "/Users/eliyoung/Stat011Project/FatigueVSFreethrow/dataProcessor.py", line 127, in process_team_games\n    pbp_data = client.play_by_play(\n        home_team=team,\n    ...<2 lines>...\n        day=day\n    )\n  File "/Users/eliyoung/Stat011Project/myenv/lib/python3.13/site-packages/basketball_reference_web_scraper/client.py", line 223, in play_by_play\n    raise InvalidDate(day=day, month=month, year=year)\nbasketball_reference_web_scraper.errors.InvalidDate: Date with year set to 1997, month set to 11, and day set to 19 is invalid\n'}
==================================================

Time: 2024-12-10 03:48:49
Error Type: ProcessTeamGamesError
Error Message: Date with year set to 1997, month set to 11, and day set to 21 is invalid
Details: {'team': 'Team.CHARLOTTE_HORNETS', 'date': '1997-11-21', 'year': 1998, 'timestamp': '2024-12-10 03:48:49', 'traceback': 'Traceback (most recent call last):\n  File "/Users/eliyoung/Stat011Project/myenv/lib/python3.13/site-packages/basketball_reference_web_scraper/client.py", line 220, in play_by_play\n    values = http_service.play_by_play(home_team=home_team, day=day, month=month, year=year)\n  File "/Users/eliyoung/Stat011Project/myenv/lib/python3.13/site-packages/basketball_reference_web_scraper/http_service.py", line 100, in play_by_play\n    response.raise_for_status()\n    ~~~~~~~~~~~~~~~~~~~~~~~~~^^\n  File "/Users/eliyoung/Stat011Project/myenv/lib/python3.13/site-packages/requests/models.py", line 1024, in raise_for_status\n    raise HTTPError(http_error_msg, response=self)\nrequests.exceptions.HTTPError: 404 Client Error: Not Found for url: https://www.basketball-reference.com/boxscores/pbp/199711210CHO.html\n\nDuring handling of the above exception, another exception occurred:\n\nTraceback (most recent call last):\n  File "/Users/eliyoung/Stat011Project/FatigueVSFreethrow/dataProcessor.py", line 890, in main\n    yearAnalyzer.process_team_games(allTeams[team], curr_date[0], curr_date[1], curr_date[2], year, attemptCounter)\n    ~~~~~~~~~~~~~~~~~~~~~~~~~~~~~~~^^^^^^^^^^^^^^^^^^^^^^^^^^^^^^^^^^^^^^^^^^^^^^^^^^^^^^^^^^^^^^^^^^^^^^^^^^^^^^^^\n  File "/Users/eliyoung/Stat011Project/FatigueVSFreethrow/dataProcessor.py", line 127, in process_team_games\n    pbp_data = client.play_by_play(\n        home_team=team,\n    ...<2 lines>...\n        day=day\n    )\n  File "/Users/eliyoung/Stat011Project/myenv/lib/python3.13/site-packages/basketball_reference_web_scraper/client.py", line 223, in play_by_play\n    raise InvalidDate(day=day, month=month, year=year)\nbasketball_reference_web_scraper.errors.InvalidDate: Date with year set to 1997, month set to 11, and day set to 21 is invalid\n'}
==================================================

Time: 2024-12-10 03:48:51
Error Type: ProcessTeamGamesError
Error Message: Date with year set to 1997, month set to 11, and day set to 25 is invalid
Details: {'team': 'Team.CHARLOTTE_HORNETS', 'date': '1997-11-25', 'year': 1998, 'timestamp': '2024-12-10 03:48:51', 'traceback': 'Traceback (most recent call last):\n  File "/Users/eliyoung/Stat011Project/myenv/lib/python3.13/site-packages/basketball_reference_web_scraper/client.py", line 220, in play_by_play\n    values = http_service.play_by_play(home_team=home_team, day=day, month=month, year=year)\n  File "/Users/eliyoung/Stat011Project/myenv/lib/python3.13/site-packages/basketball_reference_web_scraper/http_service.py", line 100, in play_by_play\n    response.raise_for_status()\n    ~~~~~~~~~~~~~~~~~~~~~~~~~^^\n  File "/Users/eliyoung/Stat011Project/myenv/lib/python3.13/site-packages/requests/models.py", line 1024, in raise_for_status\n    raise HTTPError(http_error_msg, response=self)\nrequests.exceptions.HTTPError: 404 Client Error: Not Found for url: https://www.basketball-reference.com/boxscores/pbp/199711250CHO.html\n\nDuring handling of the above exception, another exception occurred:\n\nTraceback (most recent call last):\n  File "/Users/eliyoung/Stat011Project/FatigueVSFreethrow/dataProcessor.py", line 890, in main\n    yearAnalyzer.process_team_games(allTeams[team], curr_date[0], curr_date[1], curr_date[2], year, attemptCounter)\n    ~~~~~~~~~~~~~~~~~~~~~~~~~~~~~~~^^^^^^^^^^^^^^^^^^^^^^^^^^^^^^^^^^^^^^^^^^^^^^^^^^^^^^^^^^^^^^^^^^^^^^^^^^^^^^^^\n  File "/Users/eliyoung/Stat011Project/FatigueVSFreethrow/dataProcessor.py", line 127, in process_team_games\n    pbp_data = client.play_by_play(\n        home_team=team,\n    ...<2 lines>...\n        day=day\n    )\n  File "/Users/eliyoung/Stat011Project/myenv/lib/python3.13/site-packages/basketball_reference_web_scraper/client.py", line 223, in play_by_play\n    raise InvalidDate(day=day, month=month, year=year)\nbasketball_reference_web_scraper.errors.InvalidDate: Date with year set to 1997, month set to 11, and day set to 25 is invalid\n'}
==================================================

Time: 2024-12-10 03:48:53
Error Type: ProcessTeamGamesError
Error Message: Date with year set to 1997, month set to 11, and day set to 28 is invalid
Details: {'team': 'Team.CHARLOTTE_HORNETS', 'date': '1997-11-28', 'year': 1998, 'timestamp': '2024-12-10 03:48:53', 'traceback': 'Traceback (most recent call last):\n  File "/Users/eliyoung/Stat011Project/myenv/lib/python3.13/site-packages/basketball_reference_web_scraper/client.py", line 220, in play_by_play\n    values = http_service.play_by_play(home_team=home_team, day=day, month=month, year=year)\n  File "/Users/eliyoung/Stat011Project/myenv/lib/python3.13/site-packages/basketball_reference_web_scraper/http_service.py", line 100, in play_by_play\n    response.raise_for_status()\n    ~~~~~~~~~~~~~~~~~~~~~~~~~^^\n  File "/Users/eliyoung/Stat011Project/myenv/lib/python3.13/site-packages/requests/models.py", line 1024, in raise_for_status\n    raise HTTPError(http_error_msg, response=self)\nrequests.exceptions.HTTPError: 404 Client Error: Not Found for url: https://www.basketball-reference.com/boxscores/pbp/199711280CHO.html\n\nDuring handling of the above exception, another exception occurred:\n\nTraceback (most recent call last):\n  File "/Users/eliyoung/Stat011Project/FatigueVSFreethrow/dataProcessor.py", line 890, in main\n    yearAnalyzer.process_team_games(allTeams[team], curr_date[0], curr_date[1], curr_date[2], year, attemptCounter)\n    ~~~~~~~~~~~~~~~~~~~~~~~~~~~~~~~^^^^^^^^^^^^^^^^^^^^^^^^^^^^^^^^^^^^^^^^^^^^^^^^^^^^^^^^^^^^^^^^^^^^^^^^^^^^^^^^\n  File "/Users/eliyoung/Stat011Project/FatigueVSFreethrow/dataProcessor.py", line 127, in process_team_games\n    pbp_data = client.play_by_play(\n        home_team=team,\n    ...<2 lines>...\n        day=day\n    )\n  File "/Users/eliyoung/Stat011Project/myenv/lib/python3.13/site-packages/basketball_reference_web_scraper/client.py", line 223, in play_by_play\n    raise InvalidDate(day=day, month=month, year=year)\nbasketball_reference_web_scraper.errors.InvalidDate: Date with year set to 1997, month set to 11, and day set to 28 is invalid\n'}
==================================================

Time: 2024-12-10 03:48:55
Error Type: ProcessTeamGamesError
Error Message: Date with year set to 1997, month set to 12, and day set to 02 is invalid
Details: {'team': 'Team.CHARLOTTE_HORNETS', 'date': '1997-12-02', 'year': 1998, 'timestamp': '2024-12-10 03:48:55', 'traceback': 'Traceback (most recent call last):\n  File "/Users/eliyoung/Stat011Project/myenv/lib/python3.13/site-packages/basketball_reference_web_scraper/client.py", line 220, in play_by_play\n    values = http_service.play_by_play(home_team=home_team, day=day, month=month, year=year)\n  File "/Users/eliyoung/Stat011Project/myenv/lib/python3.13/site-packages/basketball_reference_web_scraper/http_service.py", line 100, in play_by_play\n    response.raise_for_status()\n    ~~~~~~~~~~~~~~~~~~~~~~~~~^^\n  File "/Users/eliyoung/Stat011Project/myenv/lib/python3.13/site-packages/requests/models.py", line 1024, in raise_for_status\n    raise HTTPError(http_error_msg, response=self)\nrequests.exceptions.HTTPError: 404 Client Error: Not Found for url: https://www.basketball-reference.com/boxscores/pbp/199712020CHO.html\n\nDuring handling of the above exception, another exception occurred:\n\nTraceback (most recent call last):\n  File "/Users/eliyoung/Stat011Project/FatigueVSFreethrow/dataProcessor.py", line 890, in main\n    yearAnalyzer.process_team_games(allTeams[team], curr_date[0], curr_date[1], curr_date[2], year, attemptCounter)\n    ~~~~~~~~~~~~~~~~~~~~~~~~~~~~~~~^^^^^^^^^^^^^^^^^^^^^^^^^^^^^^^^^^^^^^^^^^^^^^^^^^^^^^^^^^^^^^^^^^^^^^^^^^^^^^^^\n  File "/Users/eliyoung/Stat011Project/FatigueVSFreethrow/dataProcessor.py", line 127, in process_team_games\n    pbp_data = client.play_by_play(\n        home_team=team,\n    ...<2 lines>...\n        day=day\n    )\n  File "/Users/eliyoung/Stat011Project/myenv/lib/python3.13/site-packages/basketball_reference_web_scraper/client.py", line 223, in play_by_play\n    raise InvalidDate(day=day, month=month, year=year)\nbasketball_reference_web_scraper.errors.InvalidDate: Date with year set to 1997, month set to 12, and day set to 02 is invalid\n'}
==================================================

Time: 2024-12-10 03:48:57
Error Type: ProcessTeamGamesError
Error Message: Date with year set to 1997, month set to 12, and day set to 10 is invalid
Details: {'team': 'Team.CHARLOTTE_HORNETS', 'date': '1997-12-10', 'year': 1998, 'timestamp': '2024-12-10 03:48:57', 'traceback': 'Traceback (most recent call last):\n  File "/Users/eliyoung/Stat011Project/myenv/lib/python3.13/site-packages/basketball_reference_web_scraper/client.py", line 220, in play_by_play\n    values = http_service.play_by_play(home_team=home_team, day=day, month=month, year=year)\n  File "/Users/eliyoung/Stat011Project/myenv/lib/python3.13/site-packages/basketball_reference_web_scraper/http_service.py", line 100, in play_by_play\n    response.raise_for_status()\n    ~~~~~~~~~~~~~~~~~~~~~~~~~^^\n  File "/Users/eliyoung/Stat011Project/myenv/lib/python3.13/site-packages/requests/models.py", line 1024, in raise_for_status\n    raise HTTPError(http_error_msg, response=self)\nrequests.exceptions.HTTPError: 404 Client Error: Not Found for url: https://www.basketball-reference.com/boxscores/pbp/199712100CHO.html\n\nDuring handling of the above exception, another exception occurred:\n\nTraceback (most recent call last):\n  File "/Users/eliyoung/Stat011Project/FatigueVSFreethrow/dataProcessor.py", line 890, in main\n    yearAnalyzer.process_team_games(allTeams[team], curr_date[0], curr_date[1], curr_date[2], year, attemptCounter)\n    ~~~~~~~~~~~~~~~~~~~~~~~~~~~~~~~^^^^^^^^^^^^^^^^^^^^^^^^^^^^^^^^^^^^^^^^^^^^^^^^^^^^^^^^^^^^^^^^^^^^^^^^^^^^^^^^\n  File "/Users/eliyoung/Stat011Project/FatigueVSFreethrow/dataProcessor.py", line 127, in process_team_games\n    pbp_data = client.play_by_play(\n        home_team=team,\n    ...<2 lines>...\n        day=day\n    )\n  File "/Users/eliyoung/Stat011Project/myenv/lib/python3.13/site-packages/basketball_reference_web_scraper/client.py", line 223, in play_by_play\n    raise InvalidDate(day=day, month=month, year=year)\nbasketball_reference_web_scraper.errors.InvalidDate: Date with year set to 1997, month set to 12, and day set to 10 is invalid\n'}
==================================================

Time: 2024-12-10 03:48:59
Error Type: ProcessTeamGamesError
Error Message: Date with year set to 1997, month set to 12, and day set to 12 is invalid
Details: {'team': 'Team.CHARLOTTE_HORNETS', 'date': '1997-12-12', 'year': 1998, 'timestamp': '2024-12-10 03:48:59', 'traceback': 'Traceback (most recent call last):\n  File "/Users/eliyoung/Stat011Project/myenv/lib/python3.13/site-packages/basketball_reference_web_scraper/client.py", line 220, in play_by_play\n    values = http_service.play_by_play(home_team=home_team, day=day, month=month, year=year)\n  File "/Users/eliyoung/Stat011Project/myenv/lib/python3.13/site-packages/basketball_reference_web_scraper/http_service.py", line 100, in play_by_play\n    response.raise_for_status()\n    ~~~~~~~~~~~~~~~~~~~~~~~~~^^\n  File "/Users/eliyoung/Stat011Project/myenv/lib/python3.13/site-packages/requests/models.py", line 1024, in raise_for_status\n    raise HTTPError(http_error_msg, response=self)\nrequests.exceptions.HTTPError: 404 Client Error: Not Found for url: https://www.basketball-reference.com/boxscores/pbp/199712120CHO.html\n\nDuring handling of the above exception, another exception occurred:\n\nTraceback (most recent call last):\n  File "/Users/eliyoung/Stat011Project/FatigueVSFreethrow/dataProcessor.py", line 890, in main\n    yearAnalyzer.process_team_games(allTeams[team], curr_date[0], curr_date[1], curr_date[2], year, attemptCounter)\n    ~~~~~~~~~~~~~~~~~~~~~~~~~~~~~~~^^^^^^^^^^^^^^^^^^^^^^^^^^^^^^^^^^^^^^^^^^^^^^^^^^^^^^^^^^^^^^^^^^^^^^^^^^^^^^^^\n  File "/Users/eliyoung/Stat011Project/FatigueVSFreethrow/dataProcessor.py", line 127, in process_team_games\n    pbp_data = client.play_by_play(\n        home_team=team,\n    ...<2 lines>...\n        day=day\n    )\n  File "/Users/eliyoung/Stat011Project/myenv/lib/python3.13/site-packages/basketball_reference_web_scraper/client.py", line 223, in play_by_play\n    raise InvalidDate(day=day, month=month, year=year)\nbasketball_reference_web_scraper.errors.InvalidDate: Date with year set to 1997, month set to 12, and day set to 12 is invalid\n'}
==================================================

Time: 2024-12-10 03:49:02
Error Type: ProcessTeamGamesError
Error Message: Date with year set to 1997, month set to 12, and day set to 17 is invalid
Details: {'team': 'Team.CHARLOTTE_HORNETS', 'date': '1997-12-17', 'year': 1998, 'timestamp': '2024-12-10 03:49:02', 'traceback': 'Traceback (most recent call last):\n  File "/Users/eliyoung/Stat011Project/myenv/lib/python3.13/site-packages/basketball_reference_web_scraper/client.py", line 220, in play_by_play\n    values = http_service.play_by_play(home_team=home_team, day=day, month=month, year=year)\n  File "/Users/eliyoung/Stat011Project/myenv/lib/python3.13/site-packages/basketball_reference_web_scraper/http_service.py", line 100, in play_by_play\n    response.raise_for_status()\n    ~~~~~~~~~~~~~~~~~~~~~~~~~^^\n  File "/Users/eliyoung/Stat011Project/myenv/lib/python3.13/site-packages/requests/models.py", line 1024, in raise_for_status\n    raise HTTPError(http_error_msg, response=self)\nrequests.exceptions.HTTPError: 404 Client Error: Not Found for url: https://www.basketball-reference.com/boxscores/pbp/199712170CHO.html\n\nDuring handling of the above exception, another exception occurred:\n\nTraceback (most recent call last):\n  File "/Users/eliyoung/Stat011Project/FatigueVSFreethrow/dataProcessor.py", line 890, in main\n    yearAnalyzer.process_team_games(allTeams[team], curr_date[0], curr_date[1], curr_date[2], year, attemptCounter)\n    ~~~~~~~~~~~~~~~~~~~~~~~~~~~~~~~^^^^^^^^^^^^^^^^^^^^^^^^^^^^^^^^^^^^^^^^^^^^^^^^^^^^^^^^^^^^^^^^^^^^^^^^^^^^^^^^\n  File "/Users/eliyoung/Stat011Project/FatigueVSFreethrow/dataProcessor.py", line 127, in process_team_games\n    pbp_data = client.play_by_play(\n        home_team=team,\n    ...<2 lines>...\n        day=day\n    )\n  File "/Users/eliyoung/Stat011Project/myenv/lib/python3.13/site-packages/basketball_reference_web_scraper/client.py", line 223, in play_by_play\n    raise InvalidDate(day=day, month=month, year=year)\nbasketball_reference_web_scraper.errors.InvalidDate: Date with year set to 1997, month set to 12, and day set to 17 is invalid\n'}
==================================================

Time: 2024-12-10 03:49:04
Error Type: ProcessTeamGamesError
Error Message: Date with year set to 1997, month set to 12, and day set to 20 is invalid
Details: {'team': 'Team.CHARLOTTE_HORNETS', 'date': '1997-12-20', 'year': 1998, 'timestamp': '2024-12-10 03:49:04', 'traceback': 'Traceback (most recent call last):\n  File "/Users/eliyoung/Stat011Project/myenv/lib/python3.13/site-packages/basketball_reference_web_scraper/client.py", line 220, in play_by_play\n    values = http_service.play_by_play(home_team=home_team, day=day, month=month, year=year)\n  File "/Users/eliyoung/Stat011Project/myenv/lib/python3.13/site-packages/basketball_reference_web_scraper/http_service.py", line 100, in play_by_play\n    response.raise_for_status()\n    ~~~~~~~~~~~~~~~~~~~~~~~~~^^\n  File "/Users/eliyoung/Stat011Project/myenv/lib/python3.13/site-packages/requests/models.py", line 1024, in raise_for_status\n    raise HTTPError(http_error_msg, response=self)\nrequests.exceptions.HTTPError: 404 Client Error: Not Found for url: https://www.basketball-reference.com/boxscores/pbp/199712200CHO.html\n\nDuring handling of the above exception, another exception occurred:\n\nTraceback (most recent call last):\n  File "/Users/eliyoung/Stat011Project/FatigueVSFreethrow/dataProcessor.py", line 890, in main\n    yearAnalyzer.process_team_games(allTeams[team], curr_date[0], curr_date[1], curr_date[2], year, attemptCounter)\n    ~~~~~~~~~~~~~~~~~~~~~~~~~~~~~~~^^^^^^^^^^^^^^^^^^^^^^^^^^^^^^^^^^^^^^^^^^^^^^^^^^^^^^^^^^^^^^^^^^^^^^^^^^^^^^^^\n  File "/Users/eliyoung/Stat011Project/FatigueVSFreethrow/dataProcessor.py", line 127, in process_team_games\n    pbp_data = client.play_by_play(\n        home_team=team,\n    ...<2 lines>...\n        day=day\n    )\n  File "/Users/eliyoung/Stat011Project/myenv/lib/python3.13/site-packages/basketball_reference_web_scraper/client.py", line 223, in play_by_play\n    raise InvalidDate(day=day, month=month, year=year)\nbasketball_reference_web_scraper.errors.InvalidDate: Date with year set to 1997, month set to 12, and day set to 20 is invalid\n'}
==================================================

Time: 2024-12-10 03:49:06
Error Type: ProcessTeamGamesError
Error Message: Date with year set to 1997, month set to 12, and day set to 22 is invalid
Details: {'team': 'Team.CHARLOTTE_HORNETS', 'date': '1997-12-22', 'year': 1998, 'timestamp': '2024-12-10 03:49:06', 'traceback': 'Traceback (most recent call last):\n  File "/Users/eliyoung/Stat011Project/myenv/lib/python3.13/site-packages/basketball_reference_web_scraper/client.py", line 220, in play_by_play\n    values = http_service.play_by_play(home_team=home_team, day=day, month=month, year=year)\n  File "/Users/eliyoung/Stat011Project/myenv/lib/python3.13/site-packages/basketball_reference_web_scraper/http_service.py", line 100, in play_by_play\n    response.raise_for_status()\n    ~~~~~~~~~~~~~~~~~~~~~~~~~^^\n  File "/Users/eliyoung/Stat011Project/myenv/lib/python3.13/site-packages/requests/models.py", line 1024, in raise_for_status\n    raise HTTPError(http_error_msg, response=self)\nrequests.exceptions.HTTPError: 404 Client Error: Not Found for url: https://www.basketball-reference.com/boxscores/pbp/199712220CHO.html\n\nDuring handling of the above exception, another exception occurred:\n\nTraceback (most recent call last):\n  File "/Users/eliyoung/Stat011Project/FatigueVSFreethrow/dataProcessor.py", line 890, in main\n    yearAnalyzer.process_team_games(allTeams[team], curr_date[0], curr_date[1], curr_date[2], year, attemptCounter)\n    ~~~~~~~~~~~~~~~~~~~~~~~~~~~~~~~^^^^^^^^^^^^^^^^^^^^^^^^^^^^^^^^^^^^^^^^^^^^^^^^^^^^^^^^^^^^^^^^^^^^^^^^^^^^^^^^\n  File "/Users/eliyoung/Stat011Project/FatigueVSFreethrow/dataProcessor.py", line 127, in process_team_games\n    pbp_data = client.play_by_play(\n        home_team=team,\n    ...<2 lines>...\n        day=day\n    )\n  File "/Users/eliyoung/Stat011Project/myenv/lib/python3.13/site-packages/basketball_reference_web_scraper/client.py", line 223, in play_by_play\n    raise InvalidDate(day=day, month=month, year=year)\nbasketball_reference_web_scraper.errors.InvalidDate: Date with year set to 1997, month set to 12, and day set to 22 is invalid\n'}
==================================================

Time: 2024-12-10 03:49:08
Error Type: ProcessTeamGamesError
Error Message: Date with year set to 1997, month set to 12, and day set to 26 is invalid
Details: {'team': 'Team.CHARLOTTE_HORNETS', 'date': '1997-12-26', 'year': 1998, 'timestamp': '2024-12-10 03:49:08', 'traceback': 'Traceback (most recent call last):\n  File "/Users/eliyoung/Stat011Project/myenv/lib/python3.13/site-packages/basketball_reference_web_scraper/client.py", line 220, in play_by_play\n    values = http_service.play_by_play(home_team=home_team, day=day, month=month, year=year)\n  File "/Users/eliyoung/Stat011Project/myenv/lib/python3.13/site-packages/basketball_reference_web_scraper/http_service.py", line 100, in play_by_play\n    response.raise_for_status()\n    ~~~~~~~~~~~~~~~~~~~~~~~~~^^\n  File "/Users/eliyoung/Stat011Project/myenv/lib/python3.13/site-packages/requests/models.py", line 1024, in raise_for_status\n    raise HTTPError(http_error_msg, response=self)\nrequests.exceptions.HTTPError: 404 Client Error: Not Found for url: https://www.basketball-reference.com/boxscores/pbp/199712260CHO.html\n\nDuring handling of the above exception, another exception occurred:\n\nTraceback (most recent call last):\n  File "/Users/eliyoung/Stat011Project/FatigueVSFreethrow/dataProcessor.py", line 890, in main\n    yearAnalyzer.process_team_games(allTeams[team], curr_date[0], curr_date[1], curr_date[2], year, attemptCounter)\n    ~~~~~~~~~~~~~~~~~~~~~~~~~~~~~~~^^^^^^^^^^^^^^^^^^^^^^^^^^^^^^^^^^^^^^^^^^^^^^^^^^^^^^^^^^^^^^^^^^^^^^^^^^^^^^^^\n  File "/Users/eliyoung/Stat011Project/FatigueVSFreethrow/dataProcessor.py", line 127, in process_team_games\n    pbp_data = client.play_by_play(\n        home_team=team,\n    ...<2 lines>...\n        day=day\n    )\n  File "/Users/eliyoung/Stat011Project/myenv/lib/python3.13/site-packages/basketball_reference_web_scraper/client.py", line 223, in play_by_play\n    raise InvalidDate(day=day, month=month, year=year)\nbasketball_reference_web_scraper.errors.InvalidDate: Date with year set to 1997, month set to 12, and day set to 26 is invalid\n'}
==================================================

Time: 2024-12-10 03:49:10
Error Type: ProcessTeamGamesError
Error Message: Date with year set to 1998, month set to 01, and day set to 02 is invalid
Details: {'team': 'Team.CHARLOTTE_HORNETS', 'date': '1998-01-02', 'year': 1998, 'timestamp': '2024-12-10 03:49:10', 'traceback': 'Traceback (most recent call last):\n  File "/Users/eliyoung/Stat011Project/myenv/lib/python3.13/site-packages/basketball_reference_web_scraper/client.py", line 220, in play_by_play\n    values = http_service.play_by_play(home_team=home_team, day=day, month=month, year=year)\n  File "/Users/eliyoung/Stat011Project/myenv/lib/python3.13/site-packages/basketball_reference_web_scraper/http_service.py", line 100, in play_by_play\n    response.raise_for_status()\n    ~~~~~~~~~~~~~~~~~~~~~~~~~^^\n  File "/Users/eliyoung/Stat011Project/myenv/lib/python3.13/site-packages/requests/models.py", line 1024, in raise_for_status\n    raise HTTPError(http_error_msg, response=self)\nrequests.exceptions.HTTPError: 404 Client Error: Not Found for url: https://www.basketball-reference.com/boxscores/pbp/199801020CHO.html\n\nDuring handling of the above exception, another exception occurred:\n\nTraceback (most recent call last):\n  File "/Users/eliyoung/Stat011Project/FatigueVSFreethrow/dataProcessor.py", line 890, in main\n    yearAnalyzer.process_team_games(allTeams[team], curr_date[0], curr_date[1], curr_date[2], year, attemptCounter)\n    ~~~~~~~~~~~~~~~~~~~~~~~~~~~~~~~^^^^^^^^^^^^^^^^^^^^^^^^^^^^^^^^^^^^^^^^^^^^^^^^^^^^^^^^^^^^^^^^^^^^^^^^^^^^^^^^\n  File "/Users/eliyoung/Stat011Project/FatigueVSFreethrow/dataProcessor.py", line 127, in process_team_games\n    pbp_data = client.play_by_play(\n        home_team=team,\n    ...<2 lines>...\n        day=day\n    )\n  File "/Users/eliyoung/Stat011Project/myenv/lib/python3.13/site-packages/basketball_reference_web_scraper/client.py", line 223, in play_by_play\n    raise InvalidDate(day=day, month=month, year=year)\nbasketball_reference_web_scraper.errors.InvalidDate: Date with year set to 1998, month set to 01, and day set to 02 is invalid\n'}
==================================================

Time: 2024-12-10 03:49:12
Error Type: ProcessTeamGamesError
Error Message: Date with year set to 1998, month set to 01, and day set to 13 is invalid
Details: {'team': 'Team.CHARLOTTE_HORNETS', 'date': '1998-01-13', 'year': 1998, 'timestamp': '2024-12-10 03:49:12', 'traceback': 'Traceback (most recent call last):\n  File "/Users/eliyoung/Stat011Project/myenv/lib/python3.13/site-packages/basketball_reference_web_scraper/client.py", line 220, in play_by_play\n    values = http_service.play_by_play(home_team=home_team, day=day, month=month, year=year)\n  File "/Users/eliyoung/Stat011Project/myenv/lib/python3.13/site-packages/basketball_reference_web_scraper/http_service.py", line 100, in play_by_play\n    response.raise_for_status()\n    ~~~~~~~~~~~~~~~~~~~~~~~~~^^\n  File "/Users/eliyoung/Stat011Project/myenv/lib/python3.13/site-packages/requests/models.py", line 1024, in raise_for_status\n    raise HTTPError(http_error_msg, response=self)\nrequests.exceptions.HTTPError: 404 Client Error: Not Found for url: https://www.basketball-reference.com/boxscores/pbp/199801130CHO.html\n\nDuring handling of the above exception, another exception occurred:\n\nTraceback (most recent call last):\n  File "/Users/eliyoung/Stat011Project/FatigueVSFreethrow/dataProcessor.py", line 890, in main\n    yearAnalyzer.process_team_games(allTeams[team], curr_date[0], curr_date[1], curr_date[2], year, attemptCounter)\n    ~~~~~~~~~~~~~~~~~~~~~~~~~~~~~~~^^^^^^^^^^^^^^^^^^^^^^^^^^^^^^^^^^^^^^^^^^^^^^^^^^^^^^^^^^^^^^^^^^^^^^^^^^^^^^^^\n  File "/Users/eliyoung/Stat011Project/FatigueVSFreethrow/dataProcessor.py", line 127, in process_team_games\n    pbp_data = client.play_by_play(\n        home_team=team,\n    ...<2 lines>...\n        day=day\n    )\n  File "/Users/eliyoung/Stat011Project/myenv/lib/python3.13/site-packages/basketball_reference_web_scraper/client.py", line 223, in play_by_play\n    raise InvalidDate(day=day, month=month, year=year)\nbasketball_reference_web_scraper.errors.InvalidDate: Date with year set to 1998, month set to 01, and day set to 13 is invalid\n'}
==================================================

Time: 2024-12-10 03:49:14
Error Type: ProcessTeamGamesError
Error Message: Date with year set to 1998, month set to 01, and day set to 16 is invalid
Details: {'team': 'Team.CHARLOTTE_HORNETS', 'date': '1998-01-16', 'year': 1998, 'timestamp': '2024-12-10 03:49:14', 'traceback': 'Traceback (most recent call last):\n  File "/Users/eliyoung/Stat011Project/myenv/lib/python3.13/site-packages/basketball_reference_web_scraper/client.py", line 220, in play_by_play\n    values = http_service.play_by_play(home_team=home_team, day=day, month=month, year=year)\n  File "/Users/eliyoung/Stat011Project/myenv/lib/python3.13/site-packages/basketball_reference_web_scraper/http_service.py", line 100, in play_by_play\n    response.raise_for_status()\n    ~~~~~~~~~~~~~~~~~~~~~~~~~^^\n  File "/Users/eliyoung/Stat011Project/myenv/lib/python3.13/site-packages/requests/models.py", line 1024, in raise_for_status\n    raise HTTPError(http_error_msg, response=self)\nrequests.exceptions.HTTPError: 404 Client Error: Not Found for url: https://www.basketball-reference.com/boxscores/pbp/199801160CHO.html\n\nDuring handling of the above exception, another exception occurred:\n\nTraceback (most recent call last):\n  File "/Users/eliyoung/Stat011Project/FatigueVSFreethrow/dataProcessor.py", line 890, in main\n    yearAnalyzer.process_team_games(allTeams[team], curr_date[0], curr_date[1], curr_date[2], year, attemptCounter)\n    ~~~~~~~~~~~~~~~~~~~~~~~~~~~~~~~^^^^^^^^^^^^^^^^^^^^^^^^^^^^^^^^^^^^^^^^^^^^^^^^^^^^^^^^^^^^^^^^^^^^^^^^^^^^^^^^\n  File "/Users/eliyoung/Stat011Project/FatigueVSFreethrow/dataProcessor.py", line 127, in process_team_games\n    pbp_data = client.play_by_play(\n        home_team=team,\n    ...<2 lines>...\n        day=day\n    )\n  File "/Users/eliyoung/Stat011Project/myenv/lib/python3.13/site-packages/basketball_reference_web_scraper/client.py", line 223, in play_by_play\n    raise InvalidDate(day=day, month=month, year=year)\nbasketball_reference_web_scraper.errors.InvalidDate: Date with year set to 1998, month set to 01, and day set to 16 is invalid\n'}
==================================================

Time: 2024-12-10 03:49:16
Error Type: ProcessTeamGamesError
Error Message: Date with year set to 1998, month set to 01, and day set to 19 is invalid
Details: {'team': 'Team.CHARLOTTE_HORNETS', 'date': '1998-01-19', 'year': 1998, 'timestamp': '2024-12-10 03:49:16', 'traceback': 'Traceback (most recent call last):\n  File "/Users/eliyoung/Stat011Project/myenv/lib/python3.13/site-packages/basketball_reference_web_scraper/client.py", line 220, in play_by_play\n    values = http_service.play_by_play(home_team=home_team, day=day, month=month, year=year)\n  File "/Users/eliyoung/Stat011Project/myenv/lib/python3.13/site-packages/basketball_reference_web_scraper/http_service.py", line 100, in play_by_play\n    response.raise_for_status()\n    ~~~~~~~~~~~~~~~~~~~~~~~~~^^\n  File "/Users/eliyoung/Stat011Project/myenv/lib/python3.13/site-packages/requests/models.py", line 1024, in raise_for_status\n    raise HTTPError(http_error_msg, response=self)\nrequests.exceptions.HTTPError: 404 Client Error: Not Found for url: https://www.basketball-reference.com/boxscores/pbp/199801190CHO.html\n\nDuring handling of the above exception, another exception occurred:\n\nTraceback (most recent call last):\n  File "/Users/eliyoung/Stat011Project/FatigueVSFreethrow/dataProcessor.py", line 890, in main\n    yearAnalyzer.process_team_games(allTeams[team], curr_date[0], curr_date[1], curr_date[2], year, attemptCounter)\n    ~~~~~~~~~~~~~~~~~~~~~~~~~~~~~~~^^^^^^^^^^^^^^^^^^^^^^^^^^^^^^^^^^^^^^^^^^^^^^^^^^^^^^^^^^^^^^^^^^^^^^^^^^^^^^^^\n  File "/Users/eliyoung/Stat011Project/FatigueVSFreethrow/dataProcessor.py", line 127, in process_team_games\n    pbp_data = client.play_by_play(\n        home_team=team,\n    ...<2 lines>...\n        day=day\n    )\n  File "/Users/eliyoung/Stat011Project/myenv/lib/python3.13/site-packages/basketball_reference_web_scraper/client.py", line 223, in play_by_play\n    raise InvalidDate(day=day, month=month, year=year)\nbasketball_reference_web_scraper.errors.InvalidDate: Date with year set to 1998, month set to 01, and day set to 19 is invalid\n'}
==================================================

Time: 2024-12-10 03:49:18
Error Type: ProcessTeamGamesError
Error Message: Date with year set to 1998, month set to 01, and day set to 22 is invalid
Details: {'team': 'Team.CHARLOTTE_HORNETS', 'date': '1998-01-22', 'year': 1998, 'timestamp': '2024-12-10 03:49:18', 'traceback': 'Traceback (most recent call last):\n  File "/Users/eliyoung/Stat011Project/myenv/lib/python3.13/site-packages/basketball_reference_web_scraper/client.py", line 220, in play_by_play\n    values = http_service.play_by_play(home_team=home_team, day=day, month=month, year=year)\n  File "/Users/eliyoung/Stat011Project/myenv/lib/python3.13/site-packages/basketball_reference_web_scraper/http_service.py", line 100, in play_by_play\n    response.raise_for_status()\n    ~~~~~~~~~~~~~~~~~~~~~~~~~^^\n  File "/Users/eliyoung/Stat011Project/myenv/lib/python3.13/site-packages/requests/models.py", line 1024, in raise_for_status\n    raise HTTPError(http_error_msg, response=self)\nrequests.exceptions.HTTPError: 404 Client Error: Not Found for url: https://www.basketball-reference.com/boxscores/pbp/199801220CHO.html\n\nDuring handling of the above exception, another exception occurred:\n\nTraceback (most recent call last):\n  File "/Users/eliyoung/Stat011Project/FatigueVSFreethrow/dataProcessor.py", line 890, in main\n    yearAnalyzer.process_team_games(allTeams[team], curr_date[0], curr_date[1], curr_date[2], year, attemptCounter)\n    ~~~~~~~~~~~~~~~~~~~~~~~~~~~~~~~^^^^^^^^^^^^^^^^^^^^^^^^^^^^^^^^^^^^^^^^^^^^^^^^^^^^^^^^^^^^^^^^^^^^^^^^^^^^^^^^\n  File "/Users/eliyoung/Stat011Project/FatigueVSFreethrow/dataProcessor.py", line 127, in process_team_games\n    pbp_data = client.play_by_play(\n        home_team=team,\n    ...<2 lines>...\n        day=day\n    )\n  File "/Users/eliyoung/Stat011Project/myenv/lib/python3.13/site-packages/basketball_reference_web_scraper/client.py", line 223, in play_by_play\n    raise InvalidDate(day=day, month=month, year=year)\nbasketball_reference_web_scraper.errors.InvalidDate: Date with year set to 1998, month set to 01, and day set to 22 is invalid\n'}
==================================================

Time: 2024-12-10 03:49:20
Error Type: ProcessTeamGamesError
Error Message: Date with year set to 1998, month set to 01, and day set to 27 is invalid
Details: {'team': 'Team.CHARLOTTE_HORNETS', 'date': '1998-01-27', 'year': 1998, 'timestamp': '2024-12-10 03:49:20', 'traceback': 'Traceback (most recent call last):\n  File "/Users/eliyoung/Stat011Project/myenv/lib/python3.13/site-packages/basketball_reference_web_scraper/client.py", line 220, in play_by_play\n    values = http_service.play_by_play(home_team=home_team, day=day, month=month, year=year)\n  File "/Users/eliyoung/Stat011Project/myenv/lib/python3.13/site-packages/basketball_reference_web_scraper/http_service.py", line 100, in play_by_play\n    response.raise_for_status()\n    ~~~~~~~~~~~~~~~~~~~~~~~~~^^\n  File "/Users/eliyoung/Stat011Project/myenv/lib/python3.13/site-packages/requests/models.py", line 1024, in raise_for_status\n    raise HTTPError(http_error_msg, response=self)\nrequests.exceptions.HTTPError: 404 Client Error: Not Found for url: https://www.basketball-reference.com/boxscores/pbp/199801270CHO.html\n\nDuring handling of the above exception, another exception occurred:\n\nTraceback (most recent call last):\n  File "/Users/eliyoung/Stat011Project/FatigueVSFreethrow/dataProcessor.py", line 890, in main\n    yearAnalyzer.process_team_games(allTeams[team], curr_date[0], curr_date[1], curr_date[2], year, attemptCounter)\n    ~~~~~~~~~~~~~~~~~~~~~~~~~~~~~~~^^^^^^^^^^^^^^^^^^^^^^^^^^^^^^^^^^^^^^^^^^^^^^^^^^^^^^^^^^^^^^^^^^^^^^^^^^^^^^^^\n  File "/Users/eliyoung/Stat011Project/FatigueVSFreethrow/dataProcessor.py", line 127, in process_team_games\n    pbp_data = client.play_by_play(\n        home_team=team,\n    ...<2 lines>...\n        day=day\n    )\n  File "/Users/eliyoung/Stat011Project/myenv/lib/python3.13/site-packages/basketball_reference_web_scraper/client.py", line 223, in play_by_play\n    raise InvalidDate(day=day, month=month, year=year)\nbasketball_reference_web_scraper.errors.InvalidDate: Date with year set to 1998, month set to 01, and day set to 27 is invalid\n'}
==================================================

Time: 2024-12-10 03:49:22
Error Type: ProcessTeamGamesError
Error Message: Date with year set to 1998, month set to 01, and day set to 31 is invalid
Details: {'team': 'Team.CHARLOTTE_HORNETS', 'date': '1998-01-31', 'year': 1998, 'timestamp': '2024-12-10 03:49:22', 'traceback': 'Traceback (most recent call last):\n  File "/Users/eliyoung/Stat011Project/myenv/lib/python3.13/site-packages/basketball_reference_web_scraper/client.py", line 220, in play_by_play\n    values = http_service.play_by_play(home_team=home_team, day=day, month=month, year=year)\n  File "/Users/eliyoung/Stat011Project/myenv/lib/python3.13/site-packages/basketball_reference_web_scraper/http_service.py", line 100, in play_by_play\n    response.raise_for_status()\n    ~~~~~~~~~~~~~~~~~~~~~~~~~^^\n  File "/Users/eliyoung/Stat011Project/myenv/lib/python3.13/site-packages/requests/models.py", line 1024, in raise_for_status\n    raise HTTPError(http_error_msg, response=self)\nrequests.exceptions.HTTPError: 404 Client Error: Not Found for url: https://www.basketball-reference.com/boxscores/pbp/199801310CHO.html\n\nDuring handling of the above exception, another exception occurred:\n\nTraceback (most recent call last):\n  File "/Users/eliyoung/Stat011Project/FatigueVSFreethrow/dataProcessor.py", line 890, in main\n    yearAnalyzer.process_team_games(allTeams[team], curr_date[0], curr_date[1], curr_date[2], year, attemptCounter)\n    ~~~~~~~~~~~~~~~~~~~~~~~~~~~~~~~^^^^^^^^^^^^^^^^^^^^^^^^^^^^^^^^^^^^^^^^^^^^^^^^^^^^^^^^^^^^^^^^^^^^^^^^^^^^^^^^\n  File "/Users/eliyoung/Stat011Project/FatigueVSFreethrow/dataProcessor.py", line 127, in process_team_games\n    pbp_data = client.play_by_play(\n        home_team=team,\n    ...<2 lines>...\n        day=day\n    )\n  File "/Users/eliyoung/Stat011Project/myenv/lib/python3.13/site-packages/basketball_reference_web_scraper/client.py", line 223, in play_by_play\n    raise InvalidDate(day=day, month=month, year=year)\nbasketball_reference_web_scraper.errors.InvalidDate: Date with year set to 1998, month set to 01, and day set to 31 is invalid\n'}
==================================================

Time: 2024-12-10 03:49:24
Error Type: ProcessTeamGamesError
Error Message: Date with year set to 1998, month set to 02, and day set to 03 is invalid
Details: {'team': 'Team.CHARLOTTE_HORNETS', 'date': '1998-02-03', 'year': 1998, 'timestamp': '2024-12-10 03:49:24', 'traceback': 'Traceback (most recent call last):\n  File "/Users/eliyoung/Stat011Project/myenv/lib/python3.13/site-packages/basketball_reference_web_scraper/client.py", line 220, in play_by_play\n    values = http_service.play_by_play(home_team=home_team, day=day, month=month, year=year)\n  File "/Users/eliyoung/Stat011Project/myenv/lib/python3.13/site-packages/basketball_reference_web_scraper/http_service.py", line 100, in play_by_play\n    response.raise_for_status()\n    ~~~~~~~~~~~~~~~~~~~~~~~~~^^\n  File "/Users/eliyoung/Stat011Project/myenv/lib/python3.13/site-packages/requests/models.py", line 1024, in raise_for_status\n    raise HTTPError(http_error_msg, response=self)\nrequests.exceptions.HTTPError: 404 Client Error: Not Found for url: https://www.basketball-reference.com/boxscores/pbp/199802030CHO.html\n\nDuring handling of the above exception, another exception occurred:\n\nTraceback (most recent call last):\n  File "/Users/eliyoung/Stat011Project/FatigueVSFreethrow/dataProcessor.py", line 890, in main\n    yearAnalyzer.process_team_games(allTeams[team], curr_date[0], curr_date[1], curr_date[2], year, attemptCounter)\n    ~~~~~~~~~~~~~~~~~~~~~~~~~~~~~~~^^^^^^^^^^^^^^^^^^^^^^^^^^^^^^^^^^^^^^^^^^^^^^^^^^^^^^^^^^^^^^^^^^^^^^^^^^^^^^^^\n  File "/Users/eliyoung/Stat011Project/FatigueVSFreethrow/dataProcessor.py", line 127, in process_team_games\n    pbp_data = client.play_by_play(\n        home_team=team,\n    ...<2 lines>...\n        day=day\n    )\n  File "/Users/eliyoung/Stat011Project/myenv/lib/python3.13/site-packages/basketball_reference_web_scraper/client.py", line 223, in play_by_play\n    raise InvalidDate(day=day, month=month, year=year)\nbasketball_reference_web_scraper.errors.InvalidDate: Date with year set to 1998, month set to 02, and day set to 03 is invalid\n'}
==================================================

Time: 2024-12-10 03:49:27
Error Type: ProcessTeamGamesError
Error Message: Date with year set to 1998, month set to 02, and day set to 05 is invalid
Details: {'team': 'Team.CHARLOTTE_HORNETS', 'date': '1998-02-05', 'year': 1998, 'timestamp': '2024-12-10 03:49:27', 'traceback': 'Traceback (most recent call last):\n  File "/Users/eliyoung/Stat011Project/myenv/lib/python3.13/site-packages/basketball_reference_web_scraper/client.py", line 220, in play_by_play\n    values = http_service.play_by_play(home_team=home_team, day=day, month=month, year=year)\n  File "/Users/eliyoung/Stat011Project/myenv/lib/python3.13/site-packages/basketball_reference_web_scraper/http_service.py", line 100, in play_by_play\n    response.raise_for_status()\n    ~~~~~~~~~~~~~~~~~~~~~~~~~^^\n  File "/Users/eliyoung/Stat011Project/myenv/lib/python3.13/site-packages/requests/models.py", line 1024, in raise_for_status\n    raise HTTPError(http_error_msg, response=self)\nrequests.exceptions.HTTPError: 404 Client Error: Not Found for url: https://www.basketball-reference.com/boxscores/pbp/199802050CHO.html\n\nDuring handling of the above exception, another exception occurred:\n\nTraceback (most recent call last):\n  File "/Users/eliyoung/Stat011Project/FatigueVSFreethrow/dataProcessor.py", line 890, in main\n    yearAnalyzer.process_team_games(allTeams[team], curr_date[0], curr_date[1], curr_date[2], year, attemptCounter)\n    ~~~~~~~~~~~~~~~~~~~~~~~~~~~~~~~^^^^^^^^^^^^^^^^^^^^^^^^^^^^^^^^^^^^^^^^^^^^^^^^^^^^^^^^^^^^^^^^^^^^^^^^^^^^^^^^\n  File "/Users/eliyoung/Stat011Project/FatigueVSFreethrow/dataProcessor.py", line 127, in process_team_games\n    pbp_data = client.play_by_play(\n        home_team=team,\n    ...<2 lines>...\n        day=day\n    )\n  File "/Users/eliyoung/Stat011Project/myenv/lib/python3.13/site-packages/basketball_reference_web_scraper/client.py", line 223, in play_by_play\n    raise InvalidDate(day=day, month=month, year=year)\nbasketball_reference_web_scraper.errors.InvalidDate: Date with year set to 1998, month set to 02, and day set to 05 is invalid\n'}
==================================================

Time: 2024-12-10 03:49:29
Error Type: ProcessTeamGamesError
Error Message: Date with year set to 1998, month set to 02, and day set to 11 is invalid
Details: {'team': 'Team.CHARLOTTE_HORNETS', 'date': '1998-02-11', 'year': 1998, 'timestamp': '2024-12-10 03:49:29', 'traceback': 'Traceback (most recent call last):\n  File "/Users/eliyoung/Stat011Project/myenv/lib/python3.13/site-packages/basketball_reference_web_scraper/client.py", line 220, in play_by_play\n    values = http_service.play_by_play(home_team=home_team, day=day, month=month, year=year)\n  File "/Users/eliyoung/Stat011Project/myenv/lib/python3.13/site-packages/basketball_reference_web_scraper/http_service.py", line 100, in play_by_play\n    response.raise_for_status()\n    ~~~~~~~~~~~~~~~~~~~~~~~~~^^\n  File "/Users/eliyoung/Stat011Project/myenv/lib/python3.13/site-packages/requests/models.py", line 1024, in raise_for_status\n    raise HTTPError(http_error_msg, response=self)\nrequests.exceptions.HTTPError: 404 Client Error: Not Found for url: https://www.basketball-reference.com/boxscores/pbp/199802110CHO.html\n\nDuring handling of the above exception, another exception occurred:\n\nTraceback (most recent call last):\n  File "/Users/eliyoung/Stat011Project/FatigueVSFreethrow/dataProcessor.py", line 890, in main\n    yearAnalyzer.process_team_games(allTeams[team], curr_date[0], curr_date[1], curr_date[2], year, attemptCounter)\n    ~~~~~~~~~~~~~~~~~~~~~~~~~~~~~~~^^^^^^^^^^^^^^^^^^^^^^^^^^^^^^^^^^^^^^^^^^^^^^^^^^^^^^^^^^^^^^^^^^^^^^^^^^^^^^^^\n  File "/Users/eliyoung/Stat011Project/FatigueVSFreethrow/dataProcessor.py", line 127, in process_team_games\n    pbp_data = client.play_by_play(\n        home_team=team,\n    ...<2 lines>...\n        day=day\n    )\n  File "/Users/eliyoung/Stat011Project/myenv/lib/python3.13/site-packages/basketball_reference_web_scraper/client.py", line 223, in play_by_play\n    raise InvalidDate(day=day, month=month, year=year)\nbasketball_reference_web_scraper.errors.InvalidDate: Date with year set to 1998, month set to 02, and day set to 11 is invalid\n'}
==================================================

Time: 2024-12-10 03:49:31
Error Type: ProcessTeamGamesError
Error Message: Date with year set to 1998, month set to 02, and day set to 13 is invalid
Details: {'team': 'Team.CHARLOTTE_HORNETS', 'date': '1998-02-13', 'year': 1998, 'timestamp': '2024-12-10 03:49:31', 'traceback': 'Traceback (most recent call last):\n  File "/Users/eliyoung/Stat011Project/myenv/lib/python3.13/site-packages/basketball_reference_web_scraper/client.py", line 220, in play_by_play\n    values = http_service.play_by_play(home_team=home_team, day=day, month=month, year=year)\n  File "/Users/eliyoung/Stat011Project/myenv/lib/python3.13/site-packages/basketball_reference_web_scraper/http_service.py", line 100, in play_by_play\n    response.raise_for_status()\n    ~~~~~~~~~~~~~~~~~~~~~~~~~^^\n  File "/Users/eliyoung/Stat011Project/myenv/lib/python3.13/site-packages/requests/models.py", line 1024, in raise_for_status\n    raise HTTPError(http_error_msg, response=self)\nrequests.exceptions.HTTPError: 404 Client Error: Not Found for url: https://www.basketball-reference.com/boxscores/pbp/199802130CHO.html\n\nDuring handling of the above exception, another exception occurred:\n\nTraceback (most recent call last):\n  File "/Users/eliyoung/Stat011Project/FatigueVSFreethrow/dataProcessor.py", line 890, in main\n    yearAnalyzer.process_team_games(allTeams[team], curr_date[0], curr_date[1], curr_date[2], year, attemptCounter)\n    ~~~~~~~~~~~~~~~~~~~~~~~~~~~~~~~^^^^^^^^^^^^^^^^^^^^^^^^^^^^^^^^^^^^^^^^^^^^^^^^^^^^^^^^^^^^^^^^^^^^^^^^^^^^^^^^\n  File "/Users/eliyoung/Stat011Project/FatigueVSFreethrow/dataProcessor.py", line 127, in process_team_games\n    pbp_data = client.play_by_play(\n        home_team=team,\n    ...<2 lines>...\n        day=day\n    )\n  File "/Users/eliyoung/Stat011Project/myenv/lib/python3.13/site-packages/basketball_reference_web_scraper/client.py", line 223, in play_by_play\n    raise InvalidDate(day=day, month=month, year=year)\nbasketball_reference_web_scraper.errors.InvalidDate: Date with year set to 1998, month set to 02, and day set to 13 is invalid\n'}
==================================================

Time: 2024-12-10 03:49:33
Error Type: ProcessTeamGamesError
Error Message: Date with year set to 1998, month set to 02, and day set to 28 is invalid
Details: {'team': 'Team.CHARLOTTE_HORNETS', 'date': '1998-02-28', 'year': 1998, 'timestamp': '2024-12-10 03:49:33', 'traceback': 'Traceback (most recent call last):\n  File "/Users/eliyoung/Stat011Project/myenv/lib/python3.13/site-packages/basketball_reference_web_scraper/client.py", line 220, in play_by_play\n    values = http_service.play_by_play(home_team=home_team, day=day, month=month, year=year)\n  File "/Users/eliyoung/Stat011Project/myenv/lib/python3.13/site-packages/basketball_reference_web_scraper/http_service.py", line 100, in play_by_play\n    response.raise_for_status()\n    ~~~~~~~~~~~~~~~~~~~~~~~~~^^\n  File "/Users/eliyoung/Stat011Project/myenv/lib/python3.13/site-packages/requests/models.py", line 1024, in raise_for_status\n    raise HTTPError(http_error_msg, response=self)\nrequests.exceptions.HTTPError: 404 Client Error: Not Found for url: https://www.basketball-reference.com/boxscores/pbp/199802280CHO.html\n\nDuring handling of the above exception, another exception occurred:\n\nTraceback (most recent call last):\n  File "/Users/eliyoung/Stat011Project/FatigueVSFreethrow/dataProcessor.py", line 890, in main\n    yearAnalyzer.process_team_games(allTeams[team], curr_date[0], curr_date[1], curr_date[2], year, attemptCounter)\n    ~~~~~~~~~~~~~~~~~~~~~~~~~~~~~~~^^^^^^^^^^^^^^^^^^^^^^^^^^^^^^^^^^^^^^^^^^^^^^^^^^^^^^^^^^^^^^^^^^^^^^^^^^^^^^^^\n  File "/Users/eliyoung/Stat011Project/FatigueVSFreethrow/dataProcessor.py", line 127, in process_team_games\n    pbp_data = client.play_by_play(\n        home_team=team,\n    ...<2 lines>...\n        day=day\n    )\n  File "/Users/eliyoung/Stat011Project/myenv/lib/python3.13/site-packages/basketball_reference_web_scraper/client.py", line 223, in play_by_play\n    raise InvalidDate(day=day, month=month, year=year)\nbasketball_reference_web_scraper.errors.InvalidDate: Date with year set to 1998, month set to 02, and day set to 28 is invalid\n'}
==================================================

Time: 2024-12-10 03:49:35
Error Type: ProcessTeamGamesError
Error Message: Date with year set to 1998, month set to 03, and day set to 02 is invalid
Details: {'team': 'Team.CHARLOTTE_HORNETS', 'date': '1998-03-02', 'year': 1998, 'timestamp': '2024-12-10 03:49:35', 'traceback': 'Traceback (most recent call last):\n  File "/Users/eliyoung/Stat011Project/myenv/lib/python3.13/site-packages/basketball_reference_web_scraper/client.py", line 220, in play_by_play\n    values = http_service.play_by_play(home_team=home_team, day=day, month=month, year=year)\n  File "/Users/eliyoung/Stat011Project/myenv/lib/python3.13/site-packages/basketball_reference_web_scraper/http_service.py", line 100, in play_by_play\n    response.raise_for_status()\n    ~~~~~~~~~~~~~~~~~~~~~~~~~^^\n  File "/Users/eliyoung/Stat011Project/myenv/lib/python3.13/site-packages/requests/models.py", line 1024, in raise_for_status\n    raise HTTPError(http_error_msg, response=self)\nrequests.exceptions.HTTPError: 404 Client Error: Not Found for url: https://www.basketball-reference.com/boxscores/pbp/199803020CHO.html\n\nDuring handling of the above exception, another exception occurred:\n\nTraceback (most recent call last):\n  File "/Users/eliyoung/Stat011Project/FatigueVSFreethrow/dataProcessor.py", line 890, in main\n    yearAnalyzer.process_team_games(allTeams[team], curr_date[0], curr_date[1], curr_date[2], year, attemptCounter)\n    ~~~~~~~~~~~~~~~~~~~~~~~~~~~~~~~^^^^^^^^^^^^^^^^^^^^^^^^^^^^^^^^^^^^^^^^^^^^^^^^^^^^^^^^^^^^^^^^^^^^^^^^^^^^^^^^\n  File "/Users/eliyoung/Stat011Project/FatigueVSFreethrow/dataProcessor.py", line 127, in process_team_games\n    pbp_data = client.play_by_play(\n        home_team=team,\n    ...<2 lines>...\n        day=day\n    )\n  File "/Users/eliyoung/Stat011Project/myenv/lib/python3.13/site-packages/basketball_reference_web_scraper/client.py", line 223, in play_by_play\n    raise InvalidDate(day=day, month=month, year=year)\nbasketball_reference_web_scraper.errors.InvalidDate: Date with year set to 1998, month set to 03, and day set to 02 is invalid\n'}
==================================================

Time: 2024-12-10 03:49:37
Error Type: ProcessTeamGamesError
Error Message: Date with year set to 1998, month set to 03, and day set to 04 is invalid
Details: {'team': 'Team.CHARLOTTE_HORNETS', 'date': '1998-03-04', 'year': 1998, 'timestamp': '2024-12-10 03:49:37', 'traceback': 'Traceback (most recent call last):\n  File "/Users/eliyoung/Stat011Project/myenv/lib/python3.13/site-packages/basketball_reference_web_scraper/client.py", line 220, in play_by_play\n    values = http_service.play_by_play(home_team=home_team, day=day, month=month, year=year)\n  File "/Users/eliyoung/Stat011Project/myenv/lib/python3.13/site-packages/basketball_reference_web_scraper/http_service.py", line 100, in play_by_play\n    response.raise_for_status()\n    ~~~~~~~~~~~~~~~~~~~~~~~~~^^\n  File "/Users/eliyoung/Stat011Project/myenv/lib/python3.13/site-packages/requests/models.py", line 1024, in raise_for_status\n    raise HTTPError(http_error_msg, response=self)\nrequests.exceptions.HTTPError: 404 Client Error: Not Found for url: https://www.basketball-reference.com/boxscores/pbp/199803040CHO.html\n\nDuring handling of the above exception, another exception occurred:\n\nTraceback (most recent call last):\n  File "/Users/eliyoung/Stat011Project/FatigueVSFreethrow/dataProcessor.py", line 890, in main\n    yearAnalyzer.process_team_games(allTeams[team], curr_date[0], curr_date[1], curr_date[2], year, attemptCounter)\n    ~~~~~~~~~~~~~~~~~~~~~~~~~~~~~~~^^^^^^^^^^^^^^^^^^^^^^^^^^^^^^^^^^^^^^^^^^^^^^^^^^^^^^^^^^^^^^^^^^^^^^^^^^^^^^^^\n  File "/Users/eliyoung/Stat011Project/FatigueVSFreethrow/dataProcessor.py", line 127, in process_team_games\n    pbp_data = client.play_by_play(\n        home_team=team,\n    ...<2 lines>...\n        day=day\n    )\n  File "/Users/eliyoung/Stat011Project/myenv/lib/python3.13/site-packages/basketball_reference_web_scraper/client.py", line 223, in play_by_play\n    raise InvalidDate(day=day, month=month, year=year)\nbasketball_reference_web_scraper.errors.InvalidDate: Date with year set to 1998, month set to 03, and day set to 04 is invalid\n'}
==================================================

Time: 2024-12-10 03:49:39
Error Type: ProcessTeamGamesError
Error Message: Date with year set to 1998, month set to 03, and day set to 06 is invalid
Details: {'team': 'Team.CHARLOTTE_HORNETS', 'date': '1998-03-06', 'year': 1998, 'timestamp': '2024-12-10 03:49:39', 'traceback': 'Traceback (most recent call last):\n  File "/Users/eliyoung/Stat011Project/myenv/lib/python3.13/site-packages/basketball_reference_web_scraper/client.py", line 220, in play_by_play\n    values = http_service.play_by_play(home_team=home_team, day=day, month=month, year=year)\n  File "/Users/eliyoung/Stat011Project/myenv/lib/python3.13/site-packages/basketball_reference_web_scraper/http_service.py", line 100, in play_by_play\n    response.raise_for_status()\n    ~~~~~~~~~~~~~~~~~~~~~~~~~^^\n  File "/Users/eliyoung/Stat011Project/myenv/lib/python3.13/site-packages/requests/models.py", line 1024, in raise_for_status\n    raise HTTPError(http_error_msg, response=self)\nrequests.exceptions.HTTPError: 404 Client Error: Not Found for url: https://www.basketball-reference.com/boxscores/pbp/199803060CHO.html\n\nDuring handling of the above exception, another exception occurred:\n\nTraceback (most recent call last):\n  File "/Users/eliyoung/Stat011Project/FatigueVSFreethrow/dataProcessor.py", line 890, in main\n    yearAnalyzer.process_team_games(allTeams[team], curr_date[0], curr_date[1], curr_date[2], year, attemptCounter)\n    ~~~~~~~~~~~~~~~~~~~~~~~~~~~~~~~^^^^^^^^^^^^^^^^^^^^^^^^^^^^^^^^^^^^^^^^^^^^^^^^^^^^^^^^^^^^^^^^^^^^^^^^^^^^^^^^\n  File "/Users/eliyoung/Stat011Project/FatigueVSFreethrow/dataProcessor.py", line 127, in process_team_games\n    pbp_data = client.play_by_play(\n        home_team=team,\n    ...<2 lines>...\n        day=day\n    )\n  File "/Users/eliyoung/Stat011Project/myenv/lib/python3.13/site-packages/basketball_reference_web_scraper/client.py", line 223, in play_by_play\n    raise InvalidDate(day=day, month=month, year=year)\nbasketball_reference_web_scraper.errors.InvalidDate: Date with year set to 1998, month set to 03, and day set to 06 is invalid\n'}
==================================================

Time: 2024-12-10 03:49:41
Error Type: ProcessTeamGamesError
Error Message: Date with year set to 1998, month set to 03, and day set to 11 is invalid
Details: {'team': 'Team.CHARLOTTE_HORNETS', 'date': '1998-03-11', 'year': 1998, 'timestamp': '2024-12-10 03:49:41', 'traceback': 'Traceback (most recent call last):\n  File "/Users/eliyoung/Stat011Project/myenv/lib/python3.13/site-packages/basketball_reference_web_scraper/client.py", line 220, in play_by_play\n    values = http_service.play_by_play(home_team=home_team, day=day, month=month, year=year)\n  File "/Users/eliyoung/Stat011Project/myenv/lib/python3.13/site-packages/basketball_reference_web_scraper/http_service.py", line 100, in play_by_play\n    response.raise_for_status()\n    ~~~~~~~~~~~~~~~~~~~~~~~~~^^\n  File "/Users/eliyoung/Stat011Project/myenv/lib/python3.13/site-packages/requests/models.py", line 1024, in raise_for_status\n    raise HTTPError(http_error_msg, response=self)\nrequests.exceptions.HTTPError: 404 Client Error: Not Found for url: https://www.basketball-reference.com/boxscores/pbp/199803110CHO.html\n\nDuring handling of the above exception, another exception occurred:\n\nTraceback (most recent call last):\n  File "/Users/eliyoung/Stat011Project/FatigueVSFreethrow/dataProcessor.py", line 890, in main\n    yearAnalyzer.process_team_games(allTeams[team], curr_date[0], curr_date[1], curr_date[2], year, attemptCounter)\n    ~~~~~~~~~~~~~~~~~~~~~~~~~~~~~~~^^^^^^^^^^^^^^^^^^^^^^^^^^^^^^^^^^^^^^^^^^^^^^^^^^^^^^^^^^^^^^^^^^^^^^^^^^^^^^^^\n  File "/Users/eliyoung/Stat011Project/FatigueVSFreethrow/dataProcessor.py", line 127, in process_team_games\n    pbp_data = client.play_by_play(\n        home_team=team,\n    ...<2 lines>...\n        day=day\n    )\n  File "/Users/eliyoung/Stat011Project/myenv/lib/python3.13/site-packages/basketball_reference_web_scraper/client.py", line 223, in play_by_play\n    raise InvalidDate(day=day, month=month, year=year)\nbasketball_reference_web_scraper.errors.InvalidDate: Date with year set to 1998, month set to 03, and day set to 11 is invalid\n'}
==================================================

Time: 2024-12-10 03:49:43
Error Type: ProcessTeamGamesError
Error Message: Date with year set to 1998, month set to 03, and day set to 14 is invalid
Details: {'team': 'Team.CHARLOTTE_HORNETS', 'date': '1998-03-14', 'year': 1998, 'timestamp': '2024-12-10 03:49:43', 'traceback': 'Traceback (most recent call last):\n  File "/Users/eliyoung/Stat011Project/myenv/lib/python3.13/site-packages/basketball_reference_web_scraper/client.py", line 220, in play_by_play\n    values = http_service.play_by_play(home_team=home_team, day=day, month=month, year=year)\n  File "/Users/eliyoung/Stat011Project/myenv/lib/python3.13/site-packages/basketball_reference_web_scraper/http_service.py", line 100, in play_by_play\n    response.raise_for_status()\n    ~~~~~~~~~~~~~~~~~~~~~~~~~^^\n  File "/Users/eliyoung/Stat011Project/myenv/lib/python3.13/site-packages/requests/models.py", line 1024, in raise_for_status\n    raise HTTPError(http_error_msg, response=self)\nrequests.exceptions.HTTPError: 404 Client Error: Not Found for url: https://www.basketball-reference.com/boxscores/pbp/199803140CHO.html\n\nDuring handling of the above exception, another exception occurred:\n\nTraceback (most recent call last):\n  File "/Users/eliyoung/Stat011Project/FatigueVSFreethrow/dataProcessor.py", line 890, in main\n    yearAnalyzer.process_team_games(allTeams[team], curr_date[0], curr_date[1], curr_date[2], year, attemptCounter)\n    ~~~~~~~~~~~~~~~~~~~~~~~~~~~~~~~^^^^^^^^^^^^^^^^^^^^^^^^^^^^^^^^^^^^^^^^^^^^^^^^^^^^^^^^^^^^^^^^^^^^^^^^^^^^^^^^\n  File "/Users/eliyoung/Stat011Project/FatigueVSFreethrow/dataProcessor.py", line 127, in process_team_games\n    pbp_data = client.play_by_play(\n        home_team=team,\n    ...<2 lines>...\n        day=day\n    )\n  File "/Users/eliyoung/Stat011Project/myenv/lib/python3.13/site-packages/basketball_reference_web_scraper/client.py", line 223, in play_by_play\n    raise InvalidDate(day=day, month=month, year=year)\nbasketball_reference_web_scraper.errors.InvalidDate: Date with year set to 1998, month set to 03, and day set to 14 is invalid\n'}
==================================================

Time: 2024-12-10 03:49:45
Error Type: ProcessTeamGamesError
Error Message: Date with year set to 1998, month set to 03, and day set to 16 is invalid
Details: {'team': 'Team.CHARLOTTE_HORNETS', 'date': '1998-03-16', 'year': 1998, 'timestamp': '2024-12-10 03:49:45', 'traceback': 'Traceback (most recent call last):\n  File "/Users/eliyoung/Stat011Project/myenv/lib/python3.13/site-packages/basketball_reference_web_scraper/client.py", line 220, in play_by_play\n    values = http_service.play_by_play(home_team=home_team, day=day, month=month, year=year)\n  File "/Users/eliyoung/Stat011Project/myenv/lib/python3.13/site-packages/basketball_reference_web_scraper/http_service.py", line 100, in play_by_play\n    response.raise_for_status()\n    ~~~~~~~~~~~~~~~~~~~~~~~~~^^\n  File "/Users/eliyoung/Stat011Project/myenv/lib/python3.13/site-packages/requests/models.py", line 1024, in raise_for_status\n    raise HTTPError(http_error_msg, response=self)\nrequests.exceptions.HTTPError: 404 Client Error: Not Found for url: https://www.basketball-reference.com/boxscores/pbp/199803160CHO.html\n\nDuring handling of the above exception, another exception occurred:\n\nTraceback (most recent call last):\n  File "/Users/eliyoung/Stat011Project/FatigueVSFreethrow/dataProcessor.py", line 890, in main\n    yearAnalyzer.process_team_games(allTeams[team], curr_date[0], curr_date[1], curr_date[2], year, attemptCounter)\n    ~~~~~~~~~~~~~~~~~~~~~~~~~~~~~~~^^^^^^^^^^^^^^^^^^^^^^^^^^^^^^^^^^^^^^^^^^^^^^^^^^^^^^^^^^^^^^^^^^^^^^^^^^^^^^^^\n  File "/Users/eliyoung/Stat011Project/FatigueVSFreethrow/dataProcessor.py", line 127, in process_team_games\n    pbp_data = client.play_by_play(\n        home_team=team,\n    ...<2 lines>...\n        day=day\n    )\n  File "/Users/eliyoung/Stat011Project/myenv/lib/python3.13/site-packages/basketball_reference_web_scraper/client.py", line 223, in play_by_play\n    raise InvalidDate(day=day, month=month, year=year)\nbasketball_reference_web_scraper.errors.InvalidDate: Date with year set to 1998, month set to 03, and day set to 16 is invalid\n'}
==================================================

Time: 2024-12-10 03:49:47
Error Type: ProcessTeamGamesError
Error Message: Date with year set to 1998, month set to 03, and day set to 18 is invalid
Details: {'team': 'Team.CHARLOTTE_HORNETS', 'date': '1998-03-18', 'year': 1998, 'timestamp': '2024-12-10 03:49:47', 'traceback': 'Traceback (most recent call last):\n  File "/Users/eliyoung/Stat011Project/myenv/lib/python3.13/site-packages/basketball_reference_web_scraper/client.py", line 220, in play_by_play\n    values = http_service.play_by_play(home_team=home_team, day=day, month=month, year=year)\n  File "/Users/eliyoung/Stat011Project/myenv/lib/python3.13/site-packages/basketball_reference_web_scraper/http_service.py", line 100, in play_by_play\n    response.raise_for_status()\n    ~~~~~~~~~~~~~~~~~~~~~~~~~^^\n  File "/Users/eliyoung/Stat011Project/myenv/lib/python3.13/site-packages/requests/models.py", line 1024, in raise_for_status\n    raise HTTPError(http_error_msg, response=self)\nrequests.exceptions.HTTPError: 404 Client Error: Not Found for url: https://www.basketball-reference.com/boxscores/pbp/199803180CHO.html\n\nDuring handling of the above exception, another exception occurred:\n\nTraceback (most recent call last):\n  File "/Users/eliyoung/Stat011Project/FatigueVSFreethrow/dataProcessor.py", line 890, in main\n    yearAnalyzer.process_team_games(allTeams[team], curr_date[0], curr_date[1], curr_date[2], year, attemptCounter)\n    ~~~~~~~~~~~~~~~~~~~~~~~~~~~~~~~^^^^^^^^^^^^^^^^^^^^^^^^^^^^^^^^^^^^^^^^^^^^^^^^^^^^^^^^^^^^^^^^^^^^^^^^^^^^^^^^\n  File "/Users/eliyoung/Stat011Project/FatigueVSFreethrow/dataProcessor.py", line 127, in process_team_games\n    pbp_data = client.play_by_play(\n        home_team=team,\n    ...<2 lines>...\n        day=day\n    )\n  File "/Users/eliyoung/Stat011Project/myenv/lib/python3.13/site-packages/basketball_reference_web_scraper/client.py", line 223, in play_by_play\n    raise InvalidDate(day=day, month=month, year=year)\nbasketball_reference_web_scraper.errors.InvalidDate: Date with year set to 1998, month set to 03, and day set to 18 is invalid\n'}
==================================================

Time: 2024-12-10 03:49:49
Error Type: ProcessTeamGamesError
Error Message: Date with year set to 1998, month set to 03, and day set to 26 is invalid
Details: {'team': 'Team.CHARLOTTE_HORNETS', 'date': '1998-03-26', 'year': 1998, 'timestamp': '2024-12-10 03:49:49', 'traceback': 'Traceback (most recent call last):\n  File "/Users/eliyoung/Stat011Project/myenv/lib/python3.13/site-packages/basketball_reference_web_scraper/client.py", line 220, in play_by_play\n    values = http_service.play_by_play(home_team=home_team, day=day, month=month, year=year)\n  File "/Users/eliyoung/Stat011Project/myenv/lib/python3.13/site-packages/basketball_reference_web_scraper/http_service.py", line 100, in play_by_play\n    response.raise_for_status()\n    ~~~~~~~~~~~~~~~~~~~~~~~~~^^\n  File "/Users/eliyoung/Stat011Project/myenv/lib/python3.13/site-packages/requests/models.py", line 1024, in raise_for_status\n    raise HTTPError(http_error_msg, response=self)\nrequests.exceptions.HTTPError: 404 Client Error: Not Found for url: https://www.basketball-reference.com/boxscores/pbp/199803260CHO.html\n\nDuring handling of the above exception, another exception occurred:\n\nTraceback (most recent call last):\n  File "/Users/eliyoung/Stat011Project/FatigueVSFreethrow/dataProcessor.py", line 890, in main\n    yearAnalyzer.process_team_games(allTeams[team], curr_date[0], curr_date[1], curr_date[2], year, attemptCounter)\n    ~~~~~~~~~~~~~~~~~~~~~~~~~~~~~~~^^^^^^^^^^^^^^^^^^^^^^^^^^^^^^^^^^^^^^^^^^^^^^^^^^^^^^^^^^^^^^^^^^^^^^^^^^^^^^^^\n  File "/Users/eliyoung/Stat011Project/FatigueVSFreethrow/dataProcessor.py", line 127, in process_team_games\n    pbp_data = client.play_by_play(\n        home_team=team,\n    ...<2 lines>...\n        day=day\n    )\n  File "/Users/eliyoung/Stat011Project/myenv/lib/python3.13/site-packages/basketball_reference_web_scraper/client.py", line 223, in play_by_play\n    raise InvalidDate(day=day, month=month, year=year)\nbasketball_reference_web_scraper.errors.InvalidDate: Date with year set to 1998, month set to 03, and day set to 26 is invalid\n'}
==================================================

Time: 2024-12-10 03:49:52
Error Type: ProcessTeamGamesError
Error Message: Date with year set to 1998, month set to 03, and day set to 31 is invalid
Details: {'team': 'Team.CHARLOTTE_HORNETS', 'date': '1998-03-31', 'year': 1998, 'timestamp': '2024-12-10 03:49:52', 'traceback': 'Traceback (most recent call last):\n  File "/Users/eliyoung/Stat011Project/myenv/lib/python3.13/site-packages/basketball_reference_web_scraper/client.py", line 220, in play_by_play\n    values = http_service.play_by_play(home_team=home_team, day=day, month=month, year=year)\n  File "/Users/eliyoung/Stat011Project/myenv/lib/python3.13/site-packages/basketball_reference_web_scraper/http_service.py", line 100, in play_by_play\n    response.raise_for_status()\n    ~~~~~~~~~~~~~~~~~~~~~~~~~^^\n  File "/Users/eliyoung/Stat011Project/myenv/lib/python3.13/site-packages/requests/models.py", line 1024, in raise_for_status\n    raise HTTPError(http_error_msg, response=self)\nrequests.exceptions.HTTPError: 404 Client Error: Not Found for url: https://www.basketball-reference.com/boxscores/pbp/199803310CHO.html\n\nDuring handling of the above exception, another exception occurred:\n\nTraceback (most recent call last):\n  File "/Users/eliyoung/Stat011Project/FatigueVSFreethrow/dataProcessor.py", line 890, in main\n    yearAnalyzer.process_team_games(allTeams[team], curr_date[0], curr_date[1], curr_date[2], year, attemptCounter)\n    ~~~~~~~~~~~~~~~~~~~~~~~~~~~~~~~^^^^^^^^^^^^^^^^^^^^^^^^^^^^^^^^^^^^^^^^^^^^^^^^^^^^^^^^^^^^^^^^^^^^^^^^^^^^^^^^\n  File "/Users/eliyoung/Stat011Project/FatigueVSFreethrow/dataProcessor.py", line 127, in process_team_games\n    pbp_data = client.play_by_play(\n        home_team=team,\n    ...<2 lines>...\n        day=day\n    )\n  File "/Users/eliyoung/Stat011Project/myenv/lib/python3.13/site-packages/basketball_reference_web_scraper/client.py", line 223, in play_by_play\n    raise InvalidDate(day=day, month=month, year=year)\nbasketball_reference_web_scraper.errors.InvalidDate: Date with year set to 1998, month set to 03, and day set to 31 is invalid\n'}
==================================================

Time: 2024-12-10 03:49:54
Error Type: ProcessTeamGamesError
Error Message: Date with year set to 1998, month set to 04, and day set to 03 is invalid
Details: {'team': 'Team.CHARLOTTE_HORNETS', 'date': '1998-04-03', 'year': 1998, 'timestamp': '2024-12-10 03:49:54', 'traceback': 'Traceback (most recent call last):\n  File "/Users/eliyoung/Stat011Project/myenv/lib/python3.13/site-packages/basketball_reference_web_scraper/client.py", line 220, in play_by_play\n    values = http_service.play_by_play(home_team=home_team, day=day, month=month, year=year)\n  File "/Users/eliyoung/Stat011Project/myenv/lib/python3.13/site-packages/basketball_reference_web_scraper/http_service.py", line 100, in play_by_play\n    response.raise_for_status()\n    ~~~~~~~~~~~~~~~~~~~~~~~~~^^\n  File "/Users/eliyoung/Stat011Project/myenv/lib/python3.13/site-packages/requests/models.py", line 1024, in raise_for_status\n    raise HTTPError(http_error_msg, response=self)\nrequests.exceptions.HTTPError: 404 Client Error: Not Found for url: https://www.basketball-reference.com/boxscores/pbp/199804030CHO.html\n\nDuring handling of the above exception, another exception occurred:\n\nTraceback (most recent call last):\n  File "/Users/eliyoung/Stat011Project/FatigueVSFreethrow/dataProcessor.py", line 890, in main\n    yearAnalyzer.process_team_games(allTeams[team], curr_date[0], curr_date[1], curr_date[2], year, attemptCounter)\n    ~~~~~~~~~~~~~~~~~~~~~~~~~~~~~~~^^^^^^^^^^^^^^^^^^^^^^^^^^^^^^^^^^^^^^^^^^^^^^^^^^^^^^^^^^^^^^^^^^^^^^^^^^^^^^^^\n  File "/Users/eliyoung/Stat011Project/FatigueVSFreethrow/dataProcessor.py", line 127, in process_team_games\n    pbp_data = client.play_by_play(\n        home_team=team,\n    ...<2 lines>...\n        day=day\n    )\n  File "/Users/eliyoung/Stat011Project/myenv/lib/python3.13/site-packages/basketball_reference_web_scraper/client.py", line 223, in play_by_play\n    raise InvalidDate(day=day, month=month, year=year)\nbasketball_reference_web_scraper.errors.InvalidDate: Date with year set to 1998, month set to 04, and day set to 03 is invalid\n'}
==================================================

Time: 2024-12-10 03:49:56
Error Type: ProcessTeamGamesError
Error Message: Date with year set to 1998, month set to 04, and day set to 10 is invalid
Details: {'team': 'Team.CHARLOTTE_HORNETS', 'date': '1998-04-10', 'year': 1998, 'timestamp': '2024-12-10 03:49:56', 'traceback': 'Traceback (most recent call last):\n  File "/Users/eliyoung/Stat011Project/myenv/lib/python3.13/site-packages/basketball_reference_web_scraper/client.py", line 220, in play_by_play\n    values = http_service.play_by_play(home_team=home_team, day=day, month=month, year=year)\n  File "/Users/eliyoung/Stat011Project/myenv/lib/python3.13/site-packages/basketball_reference_web_scraper/http_service.py", line 100, in play_by_play\n    response.raise_for_status()\n    ~~~~~~~~~~~~~~~~~~~~~~~~~^^\n  File "/Users/eliyoung/Stat011Project/myenv/lib/python3.13/site-packages/requests/models.py", line 1024, in raise_for_status\n    raise HTTPError(http_error_msg, response=self)\nrequests.exceptions.HTTPError: 404 Client Error: Not Found for url: https://www.basketball-reference.com/boxscores/pbp/199804100CHO.html\n\nDuring handling of the above exception, another exception occurred:\n\nTraceback (most recent call last):\n  File "/Users/eliyoung/Stat011Project/FatigueVSFreethrow/dataProcessor.py", line 890, in main\n    yearAnalyzer.process_team_games(allTeams[team], curr_date[0], curr_date[1], curr_date[2], year, attemptCounter)\n    ~~~~~~~~~~~~~~~~~~~~~~~~~~~~~~~^^^^^^^^^^^^^^^^^^^^^^^^^^^^^^^^^^^^^^^^^^^^^^^^^^^^^^^^^^^^^^^^^^^^^^^^^^^^^^^^\n  File "/Users/eliyoung/Stat011Project/FatigueVSFreethrow/dataProcessor.py", line 127, in process_team_games\n    pbp_data = client.play_by_play(\n        home_team=team,\n    ...<2 lines>...\n        day=day\n    )\n  File "/Users/eliyoung/Stat011Project/myenv/lib/python3.13/site-packages/basketball_reference_web_scraper/client.py", line 223, in play_by_play\n    raise InvalidDate(day=day, month=month, year=year)\nbasketball_reference_web_scraper.errors.InvalidDate: Date with year set to 1998, month set to 04, and day set to 10 is invalid\n'}
==================================================

Time: 2024-12-10 03:49:58
Error Type: ProcessTeamGamesError
Error Message: Date with year set to 1998, month set to 04, and day set to 12 is invalid
Details: {'team': 'Team.CHARLOTTE_HORNETS', 'date': '1998-04-12', 'year': 1998, 'timestamp': '2024-12-10 03:49:58', 'traceback': 'Traceback (most recent call last):\n  File "/Users/eliyoung/Stat011Project/myenv/lib/python3.13/site-packages/basketball_reference_web_scraper/client.py", line 220, in play_by_play\n    values = http_service.play_by_play(home_team=home_team, day=day, month=month, year=year)\n  File "/Users/eliyoung/Stat011Project/myenv/lib/python3.13/site-packages/basketball_reference_web_scraper/http_service.py", line 100, in play_by_play\n    response.raise_for_status()\n    ~~~~~~~~~~~~~~~~~~~~~~~~~^^\n  File "/Users/eliyoung/Stat011Project/myenv/lib/python3.13/site-packages/requests/models.py", line 1024, in raise_for_status\n    raise HTTPError(http_error_msg, response=self)\nrequests.exceptions.HTTPError: 404 Client Error: Not Found for url: https://www.basketball-reference.com/boxscores/pbp/199804120CHO.html\n\nDuring handling of the above exception, another exception occurred:\n\nTraceback (most recent call last):\n  File "/Users/eliyoung/Stat011Project/FatigueVSFreethrow/dataProcessor.py", line 890, in main\n    yearAnalyzer.process_team_games(allTeams[team], curr_date[0], curr_date[1], curr_date[2], year, attemptCounter)\n    ~~~~~~~~~~~~~~~~~~~~~~~~~~~~~~~^^^^^^^^^^^^^^^^^^^^^^^^^^^^^^^^^^^^^^^^^^^^^^^^^^^^^^^^^^^^^^^^^^^^^^^^^^^^^^^^\n  File "/Users/eliyoung/Stat011Project/FatigueVSFreethrow/dataProcessor.py", line 127, in process_team_games\n    pbp_data = client.play_by_play(\n        home_team=team,\n    ...<2 lines>...\n        day=day\n    )\n  File "/Users/eliyoung/Stat011Project/myenv/lib/python3.13/site-packages/basketball_reference_web_scraper/client.py", line 223, in play_by_play\n    raise InvalidDate(day=day, month=month, year=year)\nbasketball_reference_web_scraper.errors.InvalidDate: Date with year set to 1998, month set to 04, and day set to 12 is invalid\n'}
==================================================

Time: 2024-12-10 03:50:00
Error Type: ProcessTeamGamesError
Error Message: Date with year set to 1998, month set to 04, and day set to 15 is invalid
Details: {'team': 'Team.CHARLOTTE_HORNETS', 'date': '1998-04-15', 'year': 1998, 'timestamp': '2024-12-10 03:50:00', 'traceback': 'Traceback (most recent call last):\n  File "/Users/eliyoung/Stat011Project/myenv/lib/python3.13/site-packages/basketball_reference_web_scraper/client.py", line 220, in play_by_play\n    values = http_service.play_by_play(home_team=home_team, day=day, month=month, year=year)\n  File "/Users/eliyoung/Stat011Project/myenv/lib/python3.13/site-packages/basketball_reference_web_scraper/http_service.py", line 100, in play_by_play\n    response.raise_for_status()\n    ~~~~~~~~~~~~~~~~~~~~~~~~~^^\n  File "/Users/eliyoung/Stat011Project/myenv/lib/python3.13/site-packages/requests/models.py", line 1024, in raise_for_status\n    raise HTTPError(http_error_msg, response=self)\nrequests.exceptions.HTTPError: 404 Client Error: Not Found for url: https://www.basketball-reference.com/boxscores/pbp/199804150CHO.html\n\nDuring handling of the above exception, another exception occurred:\n\nTraceback (most recent call last):\n  File "/Users/eliyoung/Stat011Project/FatigueVSFreethrow/dataProcessor.py", line 890, in main\n    yearAnalyzer.process_team_games(allTeams[team], curr_date[0], curr_date[1], curr_date[2], year, attemptCounter)\n    ~~~~~~~~~~~~~~~~~~~~~~~~~~~~~~~^^^^^^^^^^^^^^^^^^^^^^^^^^^^^^^^^^^^^^^^^^^^^^^^^^^^^^^^^^^^^^^^^^^^^^^^^^^^^^^^\n  File "/Users/eliyoung/Stat011Project/FatigueVSFreethrow/dataProcessor.py", line 127, in process_team_games\n    pbp_data = client.play_by_play(\n        home_team=team,\n    ...<2 lines>...\n        day=day\n    )\n  File "/Users/eliyoung/Stat011Project/myenv/lib/python3.13/site-packages/basketball_reference_web_scraper/client.py", line 223, in play_by_play\n    raise InvalidDate(day=day, month=month, year=year)\nbasketball_reference_web_scraper.errors.InvalidDate: Date with year set to 1998, month set to 04, and day set to 15 is invalid\n'}
==================================================

Time: 2024-12-10 03:50:02
Error Type: ProcessTeamGamesError
Error Message: Date with year set to 1998, month set to 04, and day set to 19 is invalid
Details: {'team': 'Team.CHARLOTTE_HORNETS', 'date': '1998-04-19', 'year': 1998, 'timestamp': '2024-12-10 03:50:02', 'traceback': 'Traceback (most recent call last):\n  File "/Users/eliyoung/Stat011Project/myenv/lib/python3.13/site-packages/basketball_reference_web_scraper/client.py", line 220, in play_by_play\n    values = http_service.play_by_play(home_team=home_team, day=day, month=month, year=year)\n  File "/Users/eliyoung/Stat011Project/myenv/lib/python3.13/site-packages/basketball_reference_web_scraper/http_service.py", line 100, in play_by_play\n    response.raise_for_status()\n    ~~~~~~~~~~~~~~~~~~~~~~~~~^^\n  File "/Users/eliyoung/Stat011Project/myenv/lib/python3.13/site-packages/requests/models.py", line 1024, in raise_for_status\n    raise HTTPError(http_error_msg, response=self)\nrequests.exceptions.HTTPError: 404 Client Error: Not Found for url: https://www.basketball-reference.com/boxscores/pbp/199804190CHO.html\n\nDuring handling of the above exception, another exception occurred:\n\nTraceback (most recent call last):\n  File "/Users/eliyoung/Stat011Project/FatigueVSFreethrow/dataProcessor.py", line 890, in main\n    yearAnalyzer.process_team_games(allTeams[team], curr_date[0], curr_date[1], curr_date[2], year, attemptCounter)\n    ~~~~~~~~~~~~~~~~~~~~~~~~~~~~~~~^^^^^^^^^^^^^^^^^^^^^^^^^^^^^^^^^^^^^^^^^^^^^^^^^^^^^^^^^^^^^^^^^^^^^^^^^^^^^^^^\n  File "/Users/eliyoung/Stat011Project/FatigueVSFreethrow/dataProcessor.py", line 127, in process_team_games\n    pbp_data = client.play_by_play(\n        home_team=team,\n    ...<2 lines>...\n        day=day\n    )\n  File "/Users/eliyoung/Stat011Project/myenv/lib/python3.13/site-packages/basketball_reference_web_scraper/client.py", line 223, in play_by_play\n    raise InvalidDate(day=day, month=month, year=year)\nbasketball_reference_web_scraper.errors.InvalidDate: Date with year set to 1998, month set to 04, and day set to 19 is invalid\n'}
==================================================

Time: 2024-12-10 03:50:04
Error Type: ProcessTeamGamesError
Error Message: Date with year set to 1998, month set to 04, and day set to 23 is invalid
Details: {'team': 'Team.CHARLOTTE_HORNETS', 'date': '1998-04-23', 'year': 1998, 'timestamp': '2024-12-10 03:50:04', 'traceback': 'Traceback (most recent call last):\n  File "/Users/eliyoung/Stat011Project/myenv/lib/python3.13/site-packages/basketball_reference_web_scraper/client.py", line 220, in play_by_play\n    values = http_service.play_by_play(home_team=home_team, day=day, month=month, year=year)\n  File "/Users/eliyoung/Stat011Project/myenv/lib/python3.13/site-packages/basketball_reference_web_scraper/http_service.py", line 100, in play_by_play\n    response.raise_for_status()\n    ~~~~~~~~~~~~~~~~~~~~~~~~~^^\n  File "/Users/eliyoung/Stat011Project/myenv/lib/python3.13/site-packages/requests/models.py", line 1024, in raise_for_status\n    raise HTTPError(http_error_msg, response=self)\nrequests.exceptions.HTTPError: 404 Client Error: Not Found for url: https://www.basketball-reference.com/boxscores/pbp/199804230CHO.html\n\nDuring handling of the above exception, another exception occurred:\n\nTraceback (most recent call last):\n  File "/Users/eliyoung/Stat011Project/FatigueVSFreethrow/dataProcessor.py", line 890, in main\n    yearAnalyzer.process_team_games(allTeams[team], curr_date[0], curr_date[1], curr_date[2], year, attemptCounter)\n    ~~~~~~~~~~~~~~~~~~~~~~~~~~~~~~~^^^^^^^^^^^^^^^^^^^^^^^^^^^^^^^^^^^^^^^^^^^^^^^^^^^^^^^^^^^^^^^^^^^^^^^^^^^^^^^^\n  File "/Users/eliyoung/Stat011Project/FatigueVSFreethrow/dataProcessor.py", line 127, in process_team_games\n    pbp_data = client.play_by_play(\n        home_team=team,\n    ...<2 lines>...\n        day=day\n    )\n  File "/Users/eliyoung/Stat011Project/myenv/lib/python3.13/site-packages/basketball_reference_web_scraper/client.py", line 223, in play_by_play\n    raise InvalidDate(day=day, month=month, year=year)\nbasketball_reference_web_scraper.errors.InvalidDate: Date with year set to 1998, month set to 04, and day set to 23 is invalid\n'}
==================================================

Time: 2024-12-10 03:50:06
Error Type: ProcessTeamGamesError
Error Message: Date with year set to 1998, month set to 04, and day set to 25 is invalid
Details: {'team': 'Team.CHARLOTTE_HORNETS', 'date': '1998-04-25', 'year': 1998, 'timestamp': '2024-12-10 03:50:06', 'traceback': 'Traceback (most recent call last):\n  File "/Users/eliyoung/Stat011Project/myenv/lib/python3.13/site-packages/basketball_reference_web_scraper/client.py", line 220, in play_by_play\n    values = http_service.play_by_play(home_team=home_team, day=day, month=month, year=year)\n  File "/Users/eliyoung/Stat011Project/myenv/lib/python3.13/site-packages/basketball_reference_web_scraper/http_service.py", line 100, in play_by_play\n    response.raise_for_status()\n    ~~~~~~~~~~~~~~~~~~~~~~~~~^^\n  File "/Users/eliyoung/Stat011Project/myenv/lib/python3.13/site-packages/requests/models.py", line 1024, in raise_for_status\n    raise HTTPError(http_error_msg, response=self)\nrequests.exceptions.HTTPError: 404 Client Error: Not Found for url: https://www.basketball-reference.com/boxscores/pbp/199804250CHO.html\n\nDuring handling of the above exception, another exception occurred:\n\nTraceback (most recent call last):\n  File "/Users/eliyoung/Stat011Project/FatigueVSFreethrow/dataProcessor.py", line 890, in main\n    yearAnalyzer.process_team_games(allTeams[team], curr_date[0], curr_date[1], curr_date[2], year, attemptCounter)\n    ~~~~~~~~~~~~~~~~~~~~~~~~~~~~~~~^^^^^^^^^^^^^^^^^^^^^^^^^^^^^^^^^^^^^^^^^^^^^^^^^^^^^^^^^^^^^^^^^^^^^^^^^^^^^^^^\n  File "/Users/eliyoung/Stat011Project/FatigueVSFreethrow/dataProcessor.py", line 127, in process_team_games\n    pbp_data = client.play_by_play(\n        home_team=team,\n    ...<2 lines>...\n        day=day\n    )\n  File "/Users/eliyoung/Stat011Project/myenv/lib/python3.13/site-packages/basketball_reference_web_scraper/client.py", line 223, in play_by_play\n    raise InvalidDate(day=day, month=month, year=year)\nbasketball_reference_web_scraper.errors.InvalidDate: Date with year set to 1998, month set to 04, and day set to 25 is invalid\n'}
==================================================

Time: 2024-12-10 03:50:08
Error Type: ProcessTeamGamesError
Error Message: Date with year set to 1998, month set to 05, and day set to 08 is invalid
Details: {'team': 'Team.CHARLOTTE_HORNETS', 'date': '1998-05-08', 'year': 1998, 'timestamp': '2024-12-10 03:50:08', 'traceback': 'Traceback (most recent call last):\n  File "/Users/eliyoung/Stat011Project/myenv/lib/python3.13/site-packages/basketball_reference_web_scraper/client.py", line 220, in play_by_play\n    values = http_service.play_by_play(home_team=home_team, day=day, month=month, year=year)\n  File "/Users/eliyoung/Stat011Project/myenv/lib/python3.13/site-packages/basketball_reference_web_scraper/http_service.py", line 100, in play_by_play\n    response.raise_for_status()\n    ~~~~~~~~~~~~~~~~~~~~~~~~~^^\n  File "/Users/eliyoung/Stat011Project/myenv/lib/python3.13/site-packages/requests/models.py", line 1024, in raise_for_status\n    raise HTTPError(http_error_msg, response=self)\nrequests.exceptions.HTTPError: 404 Client Error: Not Found for url: https://www.basketball-reference.com/boxscores/pbp/199805080CHO.html\n\nDuring handling of the above exception, another exception occurred:\n\nTraceback (most recent call last):\n  File "/Users/eliyoung/Stat011Project/FatigueVSFreethrow/dataProcessor.py", line 890, in main\n    yearAnalyzer.process_team_games(allTeams[team], curr_date[0], curr_date[1], curr_date[2], year, attemptCounter)\n    ~~~~~~~~~~~~~~~~~~~~~~~~~~~~~~~^^^^^^^^^^^^^^^^^^^^^^^^^^^^^^^^^^^^^^^^^^^^^^^^^^^^^^^^^^^^^^^^^^^^^^^^^^^^^^^^\n  File "/Users/eliyoung/Stat011Project/FatigueVSFreethrow/dataProcessor.py", line 127, in process_team_games\n    pbp_data = client.play_by_play(\n        home_team=team,\n    ...<2 lines>...\n        day=day\n    )\n  File "/Users/eliyoung/Stat011Project/myenv/lib/python3.13/site-packages/basketball_reference_web_scraper/client.py", line 223, in play_by_play\n    raise InvalidDate(day=day, month=month, year=year)\nbasketball_reference_web_scraper.errors.InvalidDate: Date with year set to 1998, month set to 05, and day set to 08 is invalid\n'}
==================================================

Time: 2024-12-10 03:50:10
Error Type: ProcessTeamGamesError
Error Message: Date with year set to 1998, month set to 05, and day set to 10 is invalid
Details: {'team': 'Team.CHARLOTTE_HORNETS', 'date': '1998-05-10', 'year': 1998, 'timestamp': '2024-12-10 03:50:10', 'traceback': 'Traceback (most recent call last):\n  File "/Users/eliyoung/Stat011Project/myenv/lib/python3.13/site-packages/basketball_reference_web_scraper/client.py", line 220, in play_by_play\n    values = http_service.play_by_play(home_team=home_team, day=day, month=month, year=year)\n  File "/Users/eliyoung/Stat011Project/myenv/lib/python3.13/site-packages/basketball_reference_web_scraper/http_service.py", line 100, in play_by_play\n    response.raise_for_status()\n    ~~~~~~~~~~~~~~~~~~~~~~~~~^^\n  File "/Users/eliyoung/Stat011Project/myenv/lib/python3.13/site-packages/requests/models.py", line 1024, in raise_for_status\n    raise HTTPError(http_error_msg, response=self)\nrequests.exceptions.HTTPError: 404 Client Error: Not Found for url: https://www.basketball-reference.com/boxscores/pbp/199805100CHO.html\n\nDuring handling of the above exception, another exception occurred:\n\nTraceback (most recent call last):\n  File "/Users/eliyoung/Stat011Project/FatigueVSFreethrow/dataProcessor.py", line 890, in main\n    yearAnalyzer.process_team_games(allTeams[team], curr_date[0], curr_date[1], curr_date[2], year, attemptCounter)\n    ~~~~~~~~~~~~~~~~~~~~~~~~~~~~~~~^^^^^^^^^^^^^^^^^^^^^^^^^^^^^^^^^^^^^^^^^^^^^^^^^^^^^^^^^^^^^^^^^^^^^^^^^^^^^^^^\n  File "/Users/eliyoung/Stat011Project/FatigueVSFreethrow/dataProcessor.py", line 127, in process_team_games\n    pbp_data = client.play_by_play(\n        home_team=team,\n    ...<2 lines>...\n        day=day\n    )\n  File "/Users/eliyoung/Stat011Project/myenv/lib/python3.13/site-packages/basketball_reference_web_scraper/client.py", line 223, in play_by_play\n    raise InvalidDate(day=day, month=month, year=year)\nbasketball_reference_web_scraper.errors.InvalidDate: Date with year set to 1998, month set to 05, and day set to 10 is invalid\n'}
==================================================

Time: 2024-12-10 04:10:30
Error Type: ProcessTeamGamesError
Error Message: list index out of range
Details: {'team': 'Team.NEW_YORK_KNICKS', 'date': '1998-01-29', 'year': 1998, 'timestamp': '2024-12-10 04:10:30', 'traceback': 'Traceback (most recent call last):\n  File "/Users/eliyoung/Stat011Project/FatigueVSFreethrow/dataProcessor.py", line 890, in main\n    yearAnalyzer.process_team_games(allTeams[team], curr_date[0], curr_date[1], curr_date[2], year, attemptCounter)\n    ~~~~~~~~~~~~~~~~~~~~~~~~~~~~~~~^^^^^^^^^^^^^^^^^^^^^^^^^^^^^^^^^^^^^^^^^^^^^^^^^^^^^^^^^^^^^^^^^^^^^^^^^^^^^^^^\n  File "/Users/eliyoung/Stat011Project/FatigueVSFreethrow/dataProcessor.py", line 134, in process_team_games\n    self._process_game_data(pbp_data, team, year, month, day, seasonYear, attemptCounter) #passing year so I can print it\n    ~~~~~~~~~~~~~~~~~~~~~~~^^^^^^^^^^^^^^^^^^^^^^^^^^^^^^^^^^^^^^^^^^^^^^^^^^^^^^^^^^^^^^\n  File "/Users/eliyoung/Stat011Project/FatigueVSFreethrow/dataProcessor.py", line 249, in _process_game_data\n    desParsed2 = desParsed[1].split(\'for \')\n                 ~~~~~~~~~^^^\nIndexError: list index out of range\n'}
==================================================

