Error Log Started: 2024-12-07 19:40:11.344502
==================================================

Time: 2024-12-07 20:24:10
Error Type: ProcessTeamGamesError
Error Message: HTTPSConnectionPool(host='www.basketball-reference.com', port=443): Max retries exceeded with url: /boxscores/pbp/200704060SAC.html (Caused by NameResolutionError("<urllib3.connection.HTTPSConnection object at 0x10d333390>: Failed to resolve 'www.basketball-reference.com' ([Errno 8] nodename nor servname provided, or not known)"))
Details: {'team': 'Team.SACRAMENTO_KINGS', 'date': '2007-04-06', 'year': 2007, 'timestamp': '2024-12-07 20:24:10', 'traceback': 'Traceback (most recent call last):\n  File "/Users/eliyoung/Stat011Project/myenv/lib/python3.13/site-packages/urllib3/connection.py", line 199, in _new_conn\n    sock = connection.create_connection(\n        (self._dns_host, self.port),\n    ...<2 lines>...\n        socket_options=self.socket_options,\n    )\n  File "/Users/eliyoung/Stat011Project/myenv/lib/python3.13/site-packages/urllib3/util/connection.py", line 60, in create_connection\n    for res in socket.getaddrinfo(host, port, family, socket.SOCK_STREAM):\n               ~~~~~~~~~~~~~~~~~~^^^^^^^^^^^^^^^^^^^^^^^^^^^^^^^^^^^^^^^^\n  File "/opt/homebrew/Cellar/python@3.13/3.13.0_1/Frameworks/Python.framework/Versions/3.13/lib/python3.13/socket.py", line 975, in getaddrinfo\n    for res in _socket.getaddrinfo(host, port, family, type, proto, flags):\n               ~~~~~~~~~~~~~~~~~~~^^^^^^^^^^^^^^^^^^^^^^^^^^^^^^^^^^^^^^^^\nsocket.gaierror: [Errno 8] nodename nor servname provided, or not known\n\nThe above exception was the direct cause of the following exception:\n\nTraceback (most recent call last):\n  File "/Users/eliyoung/Stat011Project/myenv/lib/python3.13/site-packages/urllib3/connectionpool.py", line 789, in urlopen\n    response = self._make_request(\n        conn,\n    ...<10 lines>...\n        **response_kw,\n    )\n  File "/Users/eliyoung/Stat011Project/myenv/lib/python3.13/site-packages/urllib3/connectionpool.py", line 490, in _make_request\n    raise new_e\n  File "/Users/eliyoung/Stat011Project/myenv/lib/python3.13/site-packages/urllib3/connectionpool.py", line 466, in _make_request\n    self._validate_conn(conn)\n    ~~~~~~~~~~~~~~~~~~~^^^^^^\n  File "/Users/eliyoung/Stat011Project/myenv/lib/python3.13/site-packages/urllib3/connectionpool.py", line 1095, in _validate_conn\n    conn.connect()\n    ~~~~~~~~~~~~^^\n  File "/Users/eliyoung/Stat011Project/myenv/lib/python3.13/site-packages/urllib3/connection.py", line 693, in connect\n    self.sock = sock = self._new_conn()\n                       ~~~~~~~~~~~~~~^^\n  File "/Users/eliyoung/Stat011Project/myenv/lib/python3.13/site-packages/urllib3/connection.py", line 206, in _new_conn\n    raise NameResolutionError(self.host, self, e) from e\nurllib3.exceptions.NameResolutionError: <urllib3.connection.HTTPSConnection object at 0x10d333390>: Failed to resolve \'www.basketball-reference.com\' ([Errno 8] nodename nor servname provided, or not known)\n\nThe above exception was the direct cause of the following exception:\n\nTraceback (most recent call last):\n  File "/Users/eliyoung/Stat011Project/myenv/lib/python3.13/site-packages/requests/adapters.py", line 667, in send\n    resp = conn.urlopen(\n        method=request.method,\n    ...<9 lines>...\n        chunked=chunked,\n    )\n  File "/Users/eliyoung/Stat011Project/myenv/lib/python3.13/site-packages/urllib3/connectionpool.py", line 843, in urlopen\n    retries = retries.increment(\n        method, url, error=new_e, _pool=self, _stacktrace=sys.exc_info()[2]\n    )\n  File "/Users/eliyoung/Stat011Project/myenv/lib/python3.13/site-packages/urllib3/util/retry.py", line 519, in increment\n    raise MaxRetryError(_pool, url, reason) from reason  # type: ignore[arg-type]\n    ^^^^^^^^^^^^^^^^^^^^^^^^^^^^^^^^^^^^^^^^^^^^^^^^^^^\nurllib3.exceptions.MaxRetryError: HTTPSConnectionPool(host=\'www.basketball-reference.com\', port=443): Max retries exceeded with url: /boxscores/pbp/200704060SAC.html (Caused by NameResolutionError("<urllib3.connection.HTTPSConnection object at 0x10d333390>: Failed to resolve \'www.basketball-reference.com\' ([Errno 8] nodename nor servname provided, or not known)"))\n\nDuring handling of the above exception, another exception occurred:\n\nTraceback (most recent call last):\n  File "/Users/eliyoung/Stat011Project/FatigueVSFreethrow/specificDataProcessor.py", line 1023, in main\n    player_yearAnalyzer.process_team_games(allTeams[team], curr_date[0], curr_date[1], curr_date[2], year, player_attemptCounter, best_ft_shooters, worst_ft_shooters, bestworst)\n    ~~~~~~~~~~~~~~~~~~~~~~~~~~~~~~~~~~~~~~^^^^^^^^^^^^^^^^^^^^^^^^^^^^^^^^^^^^^^^^^^^^^^^^^^^^^^^^^^^^^^^^^^^^^^^^^^^^^^^^^^^^^^^^^^^^^^^^^^^^^^^^^^^^^^^^^^^^^^^^^^^^^^^^^^^^^^^\n  File "/Users/eliyoung/Stat011Project/FatigueVSFreethrow/specificDataProcessor.py", line 81, in process_team_games\n    pbp_data = client.play_by_play(\n        home_team=team,\n    ...<2 lines>...\n        day=day\n    )\n  File "/Users/eliyoung/Stat011Project/myenv/lib/python3.13/site-packages/basketball_reference_web_scraper/client.py", line 220, in play_by_play\n    values = http_service.play_by_play(home_team=home_team, day=day, month=month, year=year)\n  File "/Users/eliyoung/Stat011Project/myenv/lib/python3.13/site-packages/basketball_reference_web_scraper/http_service.py", line 99, in play_by_play\n    response = requests.get(url=url)\n  File "/Users/eliyoung/Stat011Project/myenv/lib/python3.13/site-packages/requests/api.py", line 73, in get\n    return request("get", url, params=params, **kwargs)\n  File "/Users/eliyoung/Stat011Project/myenv/lib/python3.13/site-packages/requests/api.py", line 59, in request\n    return session.request(method=method, url=url, **kwargs)\n           ~~~~~~~~~~~~~~~^^^^^^^^^^^^^^^^^^^^^^^^^^^^^^^^^^\n  File "/Users/eliyoung/Stat011Project/myenv/lib/python3.13/site-packages/requests/sessions.py", line 589, in request\n    resp = self.send(prep, **send_kwargs)\n  File "/Users/eliyoung/Stat011Project/myenv/lib/python3.13/site-packages/requests/sessions.py", line 703, in send\n    r = adapter.send(request, **kwargs)\n  File "/Users/eliyoung/Stat011Project/myenv/lib/python3.13/site-packages/requests/adapters.py", line 700, in send\n    raise ConnectionError(e, request=request)\nrequests.exceptions.ConnectionError: HTTPSConnectionPool(host=\'www.basketball-reference.com\', port=443): Max retries exceeded with url: /boxscores/pbp/200704060SAC.html (Caused by NameResolutionError("<urllib3.connection.HTTPSConnection object at 0x10d333390>: Failed to resolve \'www.basketball-reference.com\' ([Errno 8] nodename nor servname provided, or not known)"))\n'}
==================================================

Time: 2024-12-07 20:24:12
Error Type: ProcessTeamGamesError
Error Message: HTTPSConnectionPool(host='www.basketball-reference.com', port=443): Max retries exceeded with url: /boxscores/pbp/200704080SAC.html (Caused by NameResolutionError("<urllib3.connection.HTTPSConnection object at 0x10d402850>: Failed to resolve 'www.basketball-reference.com' ([Errno 8] nodename nor servname provided, or not known)"))
Details: {'team': 'Team.SACRAMENTO_KINGS', 'date': '2007-04-08', 'year': 2007, 'timestamp': '2024-12-07 20:24:12', 'traceback': 'Traceback (most recent call last):\n  File "/Users/eliyoung/Stat011Project/myenv/lib/python3.13/site-packages/urllib3/connection.py", line 199, in _new_conn\n    sock = connection.create_connection(\n        (self._dns_host, self.port),\n    ...<2 lines>...\n        socket_options=self.socket_options,\n    )\n  File "/Users/eliyoung/Stat011Project/myenv/lib/python3.13/site-packages/urllib3/util/connection.py", line 60, in create_connection\n    for res in socket.getaddrinfo(host, port, family, socket.SOCK_STREAM):\n               ~~~~~~~~~~~~~~~~~~^^^^^^^^^^^^^^^^^^^^^^^^^^^^^^^^^^^^^^^^\n  File "/opt/homebrew/Cellar/python@3.13/3.13.0_1/Frameworks/Python.framework/Versions/3.13/lib/python3.13/socket.py", line 975, in getaddrinfo\n    for res in _socket.getaddrinfo(host, port, family, type, proto, flags):\n               ~~~~~~~~~~~~~~~~~~~^^^^^^^^^^^^^^^^^^^^^^^^^^^^^^^^^^^^^^^^\nsocket.gaierror: [Errno 8] nodename nor servname provided, or not known\n\nThe above exception was the direct cause of the following exception:\n\nTraceback (most recent call last):\n  File "/Users/eliyoung/Stat011Project/myenv/lib/python3.13/site-packages/urllib3/connectionpool.py", line 789, in urlopen\n    response = self._make_request(\n        conn,\n    ...<10 lines>...\n        **response_kw,\n    )\n  File "/Users/eliyoung/Stat011Project/myenv/lib/python3.13/site-packages/urllib3/connectionpool.py", line 490, in _make_request\n    raise new_e\n  File "/Users/eliyoung/Stat011Project/myenv/lib/python3.13/site-packages/urllib3/connectionpool.py", line 466, in _make_request\n    self._validate_conn(conn)\n    ~~~~~~~~~~~~~~~~~~~^^^^^^\n  File "/Users/eliyoung/Stat011Project/myenv/lib/python3.13/site-packages/urllib3/connectionpool.py", line 1095, in _validate_conn\n    conn.connect()\n    ~~~~~~~~~~~~^^\n  File "/Users/eliyoung/Stat011Project/myenv/lib/python3.13/site-packages/urllib3/connection.py", line 693, in connect\n    self.sock = sock = self._new_conn()\n                       ~~~~~~~~~~~~~~^^\n  File "/Users/eliyoung/Stat011Project/myenv/lib/python3.13/site-packages/urllib3/connection.py", line 206, in _new_conn\n    raise NameResolutionError(self.host, self, e) from e\nurllib3.exceptions.NameResolutionError: <urllib3.connection.HTTPSConnection object at 0x10d402850>: Failed to resolve \'www.basketball-reference.com\' ([Errno 8] nodename nor servname provided, or not known)\n\nThe above exception was the direct cause of the following exception:\n\nTraceback (most recent call last):\n  File "/Users/eliyoung/Stat011Project/myenv/lib/python3.13/site-packages/requests/adapters.py", line 667, in send\n    resp = conn.urlopen(\n        method=request.method,\n    ...<9 lines>...\n        chunked=chunked,\n    )\n  File "/Users/eliyoung/Stat011Project/myenv/lib/python3.13/site-packages/urllib3/connectionpool.py", line 843, in urlopen\n    retries = retries.increment(\n        method, url, error=new_e, _pool=self, _stacktrace=sys.exc_info()[2]\n    )\n  File "/Users/eliyoung/Stat011Project/myenv/lib/python3.13/site-packages/urllib3/util/retry.py", line 519, in increment\n    raise MaxRetryError(_pool, url, reason) from reason  # type: ignore[arg-type]\n    ^^^^^^^^^^^^^^^^^^^^^^^^^^^^^^^^^^^^^^^^^^^^^^^^^^^\nurllib3.exceptions.MaxRetryError: HTTPSConnectionPool(host=\'www.basketball-reference.com\', port=443): Max retries exceeded with url: /boxscores/pbp/200704080SAC.html (Caused by NameResolutionError("<urllib3.connection.HTTPSConnection object at 0x10d402850>: Failed to resolve \'www.basketball-reference.com\' ([Errno 8] nodename nor servname provided, or not known)"))\n\nDuring handling of the above exception, another exception occurred:\n\nTraceback (most recent call last):\n  File "/Users/eliyoung/Stat011Project/FatigueVSFreethrow/specificDataProcessor.py", line 1023, in main\n    player_yearAnalyzer.process_team_games(allTeams[team], curr_date[0], curr_date[1], curr_date[2], year, player_attemptCounter, best_ft_shooters, worst_ft_shooters, bestworst)\n    ~~~~~~~~~~~~~~~~~~~~~~~~~~~~~~~~~~~~~~^^^^^^^^^^^^^^^^^^^^^^^^^^^^^^^^^^^^^^^^^^^^^^^^^^^^^^^^^^^^^^^^^^^^^^^^^^^^^^^^^^^^^^^^^^^^^^^^^^^^^^^^^^^^^^^^^^^^^^^^^^^^^^^^^^^^^^^\n  File "/Users/eliyoung/Stat011Project/FatigueVSFreethrow/specificDataProcessor.py", line 81, in process_team_games\n    pbp_data = client.play_by_play(\n        home_team=team,\n    ...<2 lines>...\n        day=day\n    )\n  File "/Users/eliyoung/Stat011Project/myenv/lib/python3.13/site-packages/basketball_reference_web_scraper/client.py", line 220, in play_by_play\n    values = http_service.play_by_play(home_team=home_team, day=day, month=month, year=year)\n  File "/Users/eliyoung/Stat011Project/myenv/lib/python3.13/site-packages/basketball_reference_web_scraper/http_service.py", line 99, in play_by_play\n    response = requests.get(url=url)\n  File "/Users/eliyoung/Stat011Project/myenv/lib/python3.13/site-packages/requests/api.py", line 73, in get\n    return request("get", url, params=params, **kwargs)\n  File "/Users/eliyoung/Stat011Project/myenv/lib/python3.13/site-packages/requests/api.py", line 59, in request\n    return session.request(method=method, url=url, **kwargs)\n           ~~~~~~~~~~~~~~~^^^^^^^^^^^^^^^^^^^^^^^^^^^^^^^^^^\n  File "/Users/eliyoung/Stat011Project/myenv/lib/python3.13/site-packages/requests/sessions.py", line 589, in request\n    resp = self.send(prep, **send_kwargs)\n  File "/Users/eliyoung/Stat011Project/myenv/lib/python3.13/site-packages/requests/sessions.py", line 703, in send\n    r = adapter.send(request, **kwargs)\n  File "/Users/eliyoung/Stat011Project/myenv/lib/python3.13/site-packages/requests/adapters.py", line 700, in send\n    raise ConnectionError(e, request=request)\nrequests.exceptions.ConnectionError: HTTPSConnectionPool(host=\'www.basketball-reference.com\', port=443): Max retries exceeded with url: /boxscores/pbp/200704080SAC.html (Caused by NameResolutionError("<urllib3.connection.HTTPSConnection object at 0x10d402850>: Failed to resolve \'www.basketball-reference.com\' ([Errno 8] nodename nor servname provided, or not known)"))\n'}
==================================================

Time: 2024-12-07 20:24:14
Error Type: ProcessTeamGamesError
Error Message: HTTPSConnectionPool(host='www.basketball-reference.com', port=443): Max retries exceeded with url: /boxscores/pbp/200704130SAC.html (Caused by NameResolutionError("<urllib3.connection.HTTPSConnection object at 0x10d400910>: Failed to resolve 'www.basketball-reference.com' ([Errno 8] nodename nor servname provided, or not known)"))
Details: {'team': 'Team.SACRAMENTO_KINGS', 'date': '2007-04-13', 'year': 2007, 'timestamp': '2024-12-07 20:24:14', 'traceback': 'Traceback (most recent call last):\n  File "/Users/eliyoung/Stat011Project/myenv/lib/python3.13/site-packages/urllib3/connection.py", line 199, in _new_conn\n    sock = connection.create_connection(\n        (self._dns_host, self.port),\n    ...<2 lines>...\n        socket_options=self.socket_options,\n    )\n  File "/Users/eliyoung/Stat011Project/myenv/lib/python3.13/site-packages/urllib3/util/connection.py", line 60, in create_connection\n    for res in socket.getaddrinfo(host, port, family, socket.SOCK_STREAM):\n               ~~~~~~~~~~~~~~~~~~^^^^^^^^^^^^^^^^^^^^^^^^^^^^^^^^^^^^^^^^\n  File "/opt/homebrew/Cellar/python@3.13/3.13.0_1/Frameworks/Python.framework/Versions/3.13/lib/python3.13/socket.py", line 975, in getaddrinfo\n    for res in _socket.getaddrinfo(host, port, family, type, proto, flags):\n               ~~~~~~~~~~~~~~~~~~~^^^^^^^^^^^^^^^^^^^^^^^^^^^^^^^^^^^^^^^^\nsocket.gaierror: [Errno 8] nodename nor servname provided, or not known\n\nThe above exception was the direct cause of the following exception:\n\nTraceback (most recent call last):\n  File "/Users/eliyoung/Stat011Project/myenv/lib/python3.13/site-packages/urllib3/connectionpool.py", line 789, in urlopen\n    response = self._make_request(\n        conn,\n    ...<10 lines>...\n        **response_kw,\n    )\n  File "/Users/eliyoung/Stat011Project/myenv/lib/python3.13/site-packages/urllib3/connectionpool.py", line 490, in _make_request\n    raise new_e\n  File "/Users/eliyoung/Stat011Project/myenv/lib/python3.13/site-packages/urllib3/connectionpool.py", line 466, in _make_request\n    self._validate_conn(conn)\n    ~~~~~~~~~~~~~~~~~~~^^^^^^\n  File "/Users/eliyoung/Stat011Project/myenv/lib/python3.13/site-packages/urllib3/connectionpool.py", line 1095, in _validate_conn\n    conn.connect()\n    ~~~~~~~~~~~~^^\n  File "/Users/eliyoung/Stat011Project/myenv/lib/python3.13/site-packages/urllib3/connection.py", line 693, in connect\n    self.sock = sock = self._new_conn()\n                       ~~~~~~~~~~~~~~^^\n  File "/Users/eliyoung/Stat011Project/myenv/lib/python3.13/site-packages/urllib3/connection.py", line 206, in _new_conn\n    raise NameResolutionError(self.host, self, e) from e\nurllib3.exceptions.NameResolutionError: <urllib3.connection.HTTPSConnection object at 0x10d400910>: Failed to resolve \'www.basketball-reference.com\' ([Errno 8] nodename nor servname provided, or not known)\n\nThe above exception was the direct cause of the following exception:\n\nTraceback (most recent call last):\n  File "/Users/eliyoung/Stat011Project/myenv/lib/python3.13/site-packages/requests/adapters.py", line 667, in send\n    resp = conn.urlopen(\n        method=request.method,\n    ...<9 lines>...\n        chunked=chunked,\n    )\n  File "/Users/eliyoung/Stat011Project/myenv/lib/python3.13/site-packages/urllib3/connectionpool.py", line 843, in urlopen\n    retries = retries.increment(\n        method, url, error=new_e, _pool=self, _stacktrace=sys.exc_info()[2]\n    )\n  File "/Users/eliyoung/Stat011Project/myenv/lib/python3.13/site-packages/urllib3/util/retry.py", line 519, in increment\n    raise MaxRetryError(_pool, url, reason) from reason  # type: ignore[arg-type]\n    ^^^^^^^^^^^^^^^^^^^^^^^^^^^^^^^^^^^^^^^^^^^^^^^^^^^\nurllib3.exceptions.MaxRetryError: HTTPSConnectionPool(host=\'www.basketball-reference.com\', port=443): Max retries exceeded with url: /boxscores/pbp/200704130SAC.html (Caused by NameResolutionError("<urllib3.connection.HTTPSConnection object at 0x10d400910>: Failed to resolve \'www.basketball-reference.com\' ([Errno 8] nodename nor servname provided, or not known)"))\n\nDuring handling of the above exception, another exception occurred:\n\nTraceback (most recent call last):\n  File "/Users/eliyoung/Stat011Project/FatigueVSFreethrow/specificDataProcessor.py", line 1023, in main\n    player_yearAnalyzer.process_team_games(allTeams[team], curr_date[0], curr_date[1], curr_date[2], year, player_attemptCounter, best_ft_shooters, worst_ft_shooters, bestworst)\n    ~~~~~~~~~~~~~~~~~~~~~~~~~~~~~~~~~~~~~~^^^^^^^^^^^^^^^^^^^^^^^^^^^^^^^^^^^^^^^^^^^^^^^^^^^^^^^^^^^^^^^^^^^^^^^^^^^^^^^^^^^^^^^^^^^^^^^^^^^^^^^^^^^^^^^^^^^^^^^^^^^^^^^^^^^^^^^\n  File "/Users/eliyoung/Stat011Project/FatigueVSFreethrow/specificDataProcessor.py", line 81, in process_team_games\n    pbp_data = client.play_by_play(\n        home_team=team,\n    ...<2 lines>...\n        day=day\n    )\n  File "/Users/eliyoung/Stat011Project/myenv/lib/python3.13/site-packages/basketball_reference_web_scraper/client.py", line 220, in play_by_play\n    values = http_service.play_by_play(home_team=home_team, day=day, month=month, year=year)\n  File "/Users/eliyoung/Stat011Project/myenv/lib/python3.13/site-packages/basketball_reference_web_scraper/http_service.py", line 99, in play_by_play\n    response = requests.get(url=url)\n  File "/Users/eliyoung/Stat011Project/myenv/lib/python3.13/site-packages/requests/api.py", line 73, in get\n    return request("get", url, params=params, **kwargs)\n  File "/Users/eliyoung/Stat011Project/myenv/lib/python3.13/site-packages/requests/api.py", line 59, in request\n    return session.request(method=method, url=url, **kwargs)\n           ~~~~~~~~~~~~~~~^^^^^^^^^^^^^^^^^^^^^^^^^^^^^^^^^^\n  File "/Users/eliyoung/Stat011Project/myenv/lib/python3.13/site-packages/requests/sessions.py", line 589, in request\n    resp = self.send(prep, **send_kwargs)\n  File "/Users/eliyoung/Stat011Project/myenv/lib/python3.13/site-packages/requests/sessions.py", line 703, in send\n    r = adapter.send(request, **kwargs)\n  File "/Users/eliyoung/Stat011Project/myenv/lib/python3.13/site-packages/requests/adapters.py", line 700, in send\n    raise ConnectionError(e, request=request)\nrequests.exceptions.ConnectionError: HTTPSConnectionPool(host=\'www.basketball-reference.com\', port=443): Max retries exceeded with url: /boxscores/pbp/200704130SAC.html (Caused by NameResolutionError("<urllib3.connection.HTTPSConnection object at 0x10d400910>: Failed to resolve \'www.basketball-reference.com\' ([Errno 8] nodename nor servname provided, or not known)"))\n'}
==================================================

